Workbook

Sheet BIC $6 $4
A1: January | D1: February | G1: March | J1: April | M1: May | P1: Jun | S1: Jul | V1: Aug | Y1: Sep | AB1: Oct | AE1: Nov | AH1: Dec
A2: 1 | D2: 1 | G2: 1 | J2: 1 | M2: 1 | P2: 1 | S2: 1 | V2: 1 | Y2: 1 | AB2: 1 | AE2: 1 | AH2: 1
A3: 2 | B3: -3815 | D3: 2 | E3: -1195 | G3: 2 | H3: -10335 | J3: 2 | M3: 2 | P3: 2 | S3: 2 | V3: 2 | Y3: 2 | AB3: 2 | AE3: 2 | AH3: 2
A4: 3 | D4: 3 | E4: -3318 | G4: 3 | H4: 325 | J4: 3 | M4: 3 | P4: 3 | S4: 3 | V4: 3 | Y4: 3 | AB4: 3 | AE4: 3 | AH4: 3
A5: 4 | D5: 4 | E5: -9185 | G5: 4 | J5: 4 | M5: 4 | P5: 4 | S5: 4 | V5: 4 | Y5: 4 | AB5: 4 | AE5: 4 | AH5: 4
A6: 5 | B6: 10 | D6: 5 | G6: 5 | H6: 807 | J6: 5 | M6: 5 | P6: 5 | S6: 5 | V6: 5 | Y6: 5 | AB6: 5 | AE6: 5 | AH6: 5
A7: 6 | B7: -14390 | D7: 6 | E7: -5885 | G7: 6 | H7: 12150 | J7: 6 | M7: 6 | P7: 6 | S7: 6 | V7: 6 | Y7: 6 | AB7: 6 | AE7: 6 | AH7: 6
A8: 7 | B8: -6970 | D8: 7 | G8: 7 | J8: 7 | M8: 7 | P8: 7 | S8: 7 | V8: 7 | Y8: 7 | AB8: 7 | AE8: 7 | AH8: 7
A9: 8 | B9: 670 | D9: 8 | G9: 8 | J9: 8 | M9: 8 | P9: 8 | S9: 8 | V9: 8 | Y9: 8 | AB9: 8 | AE9: 8 | AH9: 8
A10: 9 | B10: -680 | D10: 9 | E10: -6207 | G10: 9 | H10: -4135 | J10: 9 | M10: 9 | P10: 9 | S10: 9 | V10: 9 | Y10: 9 | AB10: 9 | AE10: 9 | AH10: 9
A11: 10 | D11: 10 | E11: 1910 | G11: 10 | H11: -3920 | J11: 10 | M11: 10 | P11: 10 | S11: 10 | V11: 10 | Y11: 10 | AB11: 10 | AE11: 10 | AH11: 10
A12: 11 | D12: 11 | G12: 11 | H12: 7810 | J12: 11 | M12: 11 | P12: 11 | S12: 11 | V12: 11 | Y12: 11 | AB12: 11 | AE12: 11 | AH12: 11
A13: 12 | B13: -3369 | D13: 12 | G13: 12 | H13: 2699 | J13: 12 | M13: 12 | P13: 12 | S13: 12 | V13: 12 | Y13: 12 | AB13: 12 | AE13: 12 | AH13: 12
A14: 13 | B14: 5911 | D14: 13 | E14: 9425 | G14: 13 | H14: 5005 | J14: 13 | M14: 13 | P14: 13 | S14: 13 | V14: 13 | Y14: 13 | AB14: 13 | AE14: 13 | AH14: 13
A15: 14 | B15: 205 | D15: 14 | G15: 14 | J15: 14 | M15: 14 | P15: 14 | S15: 14 | V15: 14 | Y15: 14 | AB15: 14 | AE15: 14 | AH15: 14
A16: 15 | B16: -3480 | D16: 15 | G16: 15 | J16: 15 | M16: 15 | P16: 15 | S16: 15 | V16: 15 | Y16: 15 | AB16: 15 | AE16: 15 | AH16: 15
A17: 16 | B17: 6706 | D17: 16 | G17: 16 | H17: -11714 | J17: 16 | M17: 16 | P17: 16 | S17: 16 | V17: 16 | Y17: 16 | AB17: 16 | AE17: 16 | AH17: 16
A18: 17 | D18: 17 | E18: -4620 | G18: 17 | H18: 3400 | J18: 17 | M18: 17 | P18: 17 | S18: 17 | V18: 17 | Y18: 17 | AB18: 17 | AE18: 17 | AH18: 17
A19: 18 | D19: 18 | G19: 18 | J19: 18 | M19: 18 | P19: 18 | S19: 18 | V19: 18 | Y19: 18 | AB19: 18 | AE19: 18 | AH19: 18
A20: 19 | D20: 19 | E20: 1640 | G20: 19 | H20: -3730 | J20: 19 | M20: 19 | P20: 19 | S20: 19 | V20: 19 | Y20: 19 | AB20: 19 | AE20: 19 | AH20: 19
A21: 20 | B21: 810 | D21: 20 | E21: -3645 | G21: 20 | H21: -5380 | J21: 20 | M21: 20 | P21: 20 | S21: 20 | V21: 20 | Y21: 20 | AB21: 20 | AE21: 20 | AH21: 20
A22: 21 | B22: -15525 | D22: 21 | G22: 21 | J22: 21 | M22: 21 | P22: 21 | S22: 21 | V22: 21 | Y22: 21 | AB22: 21 | AE22: 21 | AH22: 21
A23: 22 | D23: 22 | G23: 22 | J23: 22 | M23: 22 | P23: 22 | S23: 22 | V23: 22 | Y23: 22 | AB23: 22 | AE23: 22 | AH23: 22
A24: 23 | B24: -2330 | D24: 23 | E24: 1315 | G24: 23 | H24: 2270 | J24: 23 | M24: 23 | P24: 23 | S24: 23 | V24: 23 | Y24: 23 | AB24: 23 | AE24: 23 | AH24: 23
A25: 24 | D25: 24 | E25: 375 | G25: 24 | H25: 3195 | J25: 24 | M25: 24 | P25: 24 | S25: 24 | V25: 24 | Y25: 24 | AB25: 24 | AE25: 24 | AH25: 24
A26: 25 | D26: 25 | G26: 25 | H26: -625 | J26: 25 | M26: 25 | P26: 25 | S26: 25 | V26: 25 | Y26: 25 | AB26: 25 | AE26: 25 | AH26: 25
A27: 26 | B27: 9445 | D27: 26 | G27: 26 | H27: 2310 | J27: 26 | M27: 26 | P27: 26 | S27: 26 | V27: 26 | Y27: 26 | AB27: 26 | AE27: 26 | AH27: 26
A28: 27 | B28: 5390 | D28: 27 | E28: 6880 | G28: 27 | H28: 5400 | J28: 27 | M28: 27 | P28: 27 | S28: 27 | V28: 27 | Y28: 27 | AB28: 27 | AE28: 27 | AH28: 27
A29: 28 | D29: 28 | G29: 28 | J29: 28 | M29: 28 | P29: 28 | S29: 28 | V29: 28 | Y29: 28 | AB29: 28 | AE29: 28 | AH29: 28
A30: 29 | D30: 29 | G30: 29 | J30: 29 | M30: 29 | P30: 29 | S30: 29 | V30: 29 | Y30: 29 | AB30: 29 | AE30: 29 | AH30: 29
A31: 30 | B31: -2420 | D31: 30 | G31: 30 | H31: 2265 | J31: 30 | M31: 30 | P31: 30 | S31: 30 | V31: 30 | Y31: 30 | AB31: 30 | AE31: 30 | AH31: 30
A32: 31 | D32: 31 | G32: 31 | H32: 215 | J32: 31 | M32: 31 | P32: 31 | S32: 31 | V32: 31 | Y32: 31 | AB32: 31 | AE32: 31 | AH32: 31
A35: Total | B35: =SUM(B2:B34) | E35: =SUM(E2:E34) | H35: =SUM(H2:H34) | K35: =SUM(K2:K34) | N35: =SUM(N2:N34) | Q35: =SUM(Q2:Q34) | T35: =SUM(T2:T34) | W35: =SUM(W2:W34) | Z35: =SUM(Z2:Z34) | AC35: =SUM(AC2:AC34) | AF35: =SUM(AF2:AF34) | AI35: =SUM(AI2:AI34)

Sheet BIC Standard
A1: January | D1: February | G1: March | J1: April | M1: May | P1: Jun | S1: Jul | V1: Aug | Y1: Sep | AB1: Oct | AE1: Nov | AH1: Dec
A2: 1 | D2: 1 | G2: 1 | J2: 1 | M2: 1 | P2: 1 | S2: 1 | V2: 1 | Y2: 1 | AB2: 1 | AE2: 1 | AH2: 1
A3: 2 | D3: 2 | G3: 2 | H3: -9880 | J3: 2 | M3: 2 | P3: 2 | S3: 2 | V3: 2 | Y3: 2 | AB3: 2 | AE3: 2 | AH3: 2
A4: 3 | D4: 3 | G4: 3 | H4: -5970 | J4: 3 | M4: 3 | P4: 3 | S4: 3 | V4: 3 | Y4: 3 | AB4: 3 | AE4: 3 | AH4: 3
A5: 4 | D5: 4 | G5: 4 | H5: 6995 | J5: 4 | M5: 4 | P5: 4 | S5: 4 | V5: 4 | Y5: 4 | AB5: 4 | AE5: 4 | AH5: 4
A6: 5 | D6: 5 | G6: 5 | H6: -2330 | J6: 5 | M6: 5 | P6: 5 | S6: 5 | V6: 5 | Y6: 5 | AB6: 5 | AE6: 5 | AH6: 5
A7: 6 | D7: 6 | G7: 6 | H7: 9915 | J7: 6 | M7: 6 | P7: 6 | S7: 6 | V7: 6 | Y7: 6 | AB7: 6 | AE7: 6 | AH7: 6
A8: 7 | D8: 7 | G8: 7 | J8: 7 | M8: 7 | P8: 7 | S8: 7 | V8: 7 | Y8: 7 | AB8: 7 | AE8: 7 | AH8: 7
A9: 8 | D9: 8 | G9: 8 | J9: 8 | M9: 8 | P9: 8 | S9: 8 | V9: 8 | Y9: 8 | AB9: 8 | AE9: 8 | AH9: 8
A10: 9 | D10: 9 | G10: 9 | H10: -9240 | J10: 9 | M10: 9 | P10: 9 | S10: 9 | V10: 9 | Y10: 9 | AB10: 9 | AE10: 9 | AH10: 9
A11: 10 | D11: 10 | G11: 10 | H11: -7975 | J11: 10 | M11: 10 | P11: 10 | S11: 10 | V11: 10 | Y11: 10 | AB11: 10 | AE11: 10 | AH11: 10
A12: 11 | D12: 11 | G12: 11 | H12: 665 | J12: 11 | M12: 11 | P12: 11 | S12: 11 | V12: 11 | Y12: 11 | AB12: 11 | AE12: 11 | AH12: 11
A13: 12 | D13: 12 | E13: -920 | G13: 12 | H13: 11930 | J13: 12 | M13: 12 | P13: 12 | S13: 12 | V13: 12 | Y13: 12 | AB13: 12 | AE13: 12 | AH13: 12
A14: 13 | D14: 13 | E14: 800 | G14: 13 | H14: 9500 | J14: 13 | M14: 13 | P14: 13 | S14: 13 | V14: 13 | Y14: 13 | AB14: 13 | AE14: 13 | AH14: 13
A15: 14 | D15: 14 | G15: 14 | J15: 14 | M15: 14 | P15: 14 | S15: 14 | V15: 14 | Y15: 14 | AB15: 14 | AE15: 14 | AH15: 14
A16: 15 | D16: 15 | G16: 15 | J16: 15 | M16: 15 | P16: 15 | S16: 15 | V16: 15 | Y16: 15 | AB16: 15 | AE16: 15 | AH16: 15
A17: 16 | D17: 16 | G17: 16 | H17: 4420 | J17: 16 | M17: 16 | P17: 16 | S17: 16 | V17: 16 | Y17: 16 | AB17: 16 | AE17: 16 | AH17: 16
A18: 17 | D18: 17 | E18: 370 | G18: 17 | H18: 6895 | J18: 17 | M18: 17 | P18: 17 | S18: 17 | V18: 17 | Y18: 17 | AB18: 17 | AE18: 17 | AH18: 17
A19: 18 | D19: 18 | E19: 790 | G19: 18 | H19: 1170 | J19: 18 | M19: 18 | P19: 18 | S19: 18 | V19: 18 | Y19: 18 | AB19: 18 | AE19: 18 | AH19: 18
A20: 19 | D20: 19 | E20: 3357 | G20: 19 | H20: -1335 | J20: 19 | M20: 19 | P20: 19 | S20: 19 | V20: 19 | Y20: 19 | AB20: 19 | AE20: 19 | AH20: 19
A21: 20 | D21: 20 | E21: 1895 | G21: 20 | H21: -4240 | J21: 20 | M21: 20 | P21: 20 | S21: 20 | V21: 20 | Y21: 20 | AB21: 20 | AE21: 20 | AH21: 20
A22: 21 | D22: 21 | G22: 21 | J22: 21 | M22: 21 | P22: 21 | S22: 21 | V22: 21 | Y22: 21 | AB22: 21 | AE22: 21 | AH22: 21
A23: 22 | D23: 22 | G23: 22 | J23: 22 | M23: 22 | P23: 22 | S23: 22 | V23: 22 | Y23: 22 | AB23: 22 | AE23: 22 | AH23: 22
A24: 23 | D24: 23 | E24: 450 | G24: 23 | H24: -1835 | J24: 23 | M24: 23 | P24: 23 | S24: 23 | V24: 23 | Y24: 23 | AB24: 23 | AE24: 23 | AH24: 23
A25: 24 | D25: 24 | E25: 1140 | G25: 24 | H25: -4205 | J25: 24 | M25: 24 | P25: 24 | S25: 24 | V25: 24 | Y25: 24 | AB25: 24 | AE25: 24 | AH25: 24
A26: 25 | D26: 25 | E26: 1266 | G26: 25 | H26: -3540 | J26: 25 | M26: 25 | P26: 25 | S26: 25 | V26: 25 | Y26: 25 | AB26: 25 | AE26: 25 | AH26: 25
A27: 26 | D27: 26 | E27: 9240 | G27: 26 | H27: 5500 | J27: 26 | M27: 26 | P27: 26 | S27: 26 | V27: 26 | Y27: 26 | AB27: 26 | AE27: 26 | AH27: 26
A28: 27 | D28: 27 | E28: 1995 | G28: 27 | H28: 3205 | J28: 27 | M28: 27 | P28: 27 | S28: 27 | V28: 27 | Y28: 27 | AB28: 27 | AE28: 27 | AH28: 27
A29: 28 | D29: 28 | G29: 28 | J29: 28 | M29: 28 | P29: 28 | S29: 28 | V29: 28 | Y29: 28 | AB29: 28 | AE29: 28 | AH29: 28
A30: 29 | D30: 29 | G30: 29 | J30: 29 | M30: 29 | P30: 29 | S30: 29 | V30: 29 | Y30: 29 | AB30: 29 | AE30: 29 | AH30: 29
A31: 30 | D31: 30 | G31: 30 | H31: 4745 | J31: 30 | M31: 30 | P31: 30 | S31: 30 | V31: 30 | Y31: 30 | AB31: 30 | AE31: 30 | AH31: 30
A32: 31 | D32: 31 | G32: 31 | H32: -1353 | J32: 31 | M32: 31 | P32: 31 | S32: 31 | V32: 31 | Y32: 31 | AB32: 31 | AE32: 31 | AH32: 31
A35: Total | E35: =SUM(E2:E28) | H35: =SUM(H2:H34) | K35: =SUM(K2:K34) | N35: =SUM(N2:N34) | Q35: =SUM(Q2:Q34) | T35: =SUM(T2:T34) | W35: =SUM(W2:W34) | Z35: =SUM(Z2:Z34) | AC35: =SUM(AC2:AC34) | AF35: =SUM(AF2:AF34) | AI35: =SUM(AI2:AI34)

Sheet BIC $4 
A1: January | D1: February | G1: March | J1: April | M1: May | P1: Jun | S1: Jul | V1: Aug | Y1: Sep | AB1: Oct | AE1: Nov | AH1: Dec
A2: 1 | D2: 1 | G2: 1 | J2: 1 | M2: 1 | P2: 1 | S2: 1 | V2: 1 | Y2: 1 | AB2: 1 | AE2: 1 | AH2: 1
A3: 2 | B3: -3940 | D3: 2 | E3: -660 | G3: 2 | H3: -5880 | J3: 2 | M3: 2 | P3: 2 | S3: 2 | V3: 2 | Y3: 2 | AB3: 2 | AE3: 2 | AH3: 2
A4: 3 | D4: 3 | E4: 210 | G4: 3 | J4: 3 | M4: 3 | P4: 3 | S4: 3 | V4: 3 | Y4: 3 | AB4: 3 | AE4: 3 | AH4: 3
A5: 4 | D5: 4 | E5: -1895 | G5: 4 | H5: 3150 | J5: 4 | M5: 4 | P5: 4 | S5: 4 | V5: 4 | Y5: 4 | AB5: 4 | AE5: 4 | AH5: 4
A6: 5 | B6: 685 | D6: 5 | G6: 5 | J6: 5 | M6: 5 | P6: 5 | S6: 5 | V6: 5 | Y6: 5 | AB6: 5 | AE6: 5 | AH6: 5
A7: 6 | B7: -5030 | D7: 6 | E7: -1110 | G7: 6 | H7: 45 | J7: 6 | M7: 6 | P7: 6 | S7: 6 | V7: 6 | Y7: 6 | AB7: 6 | AE7: 6 | AH7: 6
A8: 7 | B8: -235 | D8: 7 | G8: 7 | J8: 7 | M8: 7 | P8: 7 | S8: 7 | V8: 7 | Y8: 7 | AB8: 7 | AE8: 7 | AH8: 7
A9: 8 | D9: 8 | G9: 8 | J9: 8 | M9: 8 | P9: 8 | S9: 8 | V9: 8 | Y9: 8 | AB9: 8 | AE9: 8 | AH9: 8
A10: 9 | B10: 1151 | D10: 9 | E10: -1126 | G10: 9 | H10: -5430 | J10: 9 | M10: 9 | P10: 9 | S10: 9 | V10: 9 | Y10: 9 | AB10: 9 | AE10: 9 | AH10: 9
A11: 10 | D11: 10 | E11: 720 | G11: 10 | J11: 10 | M11: 10 | P11: 10 | S11: 10 | V11: 10 | Y11: 10 | AB11: 10 | AE11: 10 | AH11: 10
A12: 11 | D12: 11 | E12: 40 | G12: 11 | H12: 3330 | J12: 11 | M12: 11 | P12: 11 | S12: 11 | V12: 11 | Y12: 11 | AB12: 11 | AE12: 11 | AH12: 11
A13: 12 | B13: -1040 | D13: 12 | E13: 180 | G13: 12 | J13: 12 | M13: 12 | P13: 12 | S13: 12 | V13: 12 | Y13: 12 | AB13: 12 | AE13: 12 | AH13: 12
A14: 13 | B14: 1401 | D14: 13 | E14: 645 | G14: 13 | H14: 60 | J14: 13 | M14: 13 | P14: 13 | S14: 13 | V14: 13 | Y14: 13 | AB14: 13 | AE14: 13 | AH14: 13
A15: 14 | B15: -780 | D15: 14 | G15: 14 | J15: 14 | M15: 14 | P15: 14 | S15: 14 | V15: 14 | Y15: 14 | AB15: 14 | AE15: 14 | AH15: 14
A16: 15 | B16: 115 | D16: 15 | G16: 15 | J16: 15 | M16: 15 | P16: 15 | S16: 15 | V16: 15 | Y16: 15 | AB16: 15 | AE16: 15 | AH16: 15
A17: 16 | B17: -2190 | D17: 16 | G17: 16 | H17: -8430 | J17: 16 | M17: 16 | P17: 16 | S17: 16 | V17: 16 | Y17: 16 | AB17: 16 | AE17: 16 | AH17: 16
A18: 17 | D18: 17 | E18: 40 | G18: 17 | J18: 17 | M18: 17 | P18: 17 | S18: 17 | V18: 17 | Y18: 17 | AB18: 17 | AE18: 17 | AH18: 17
A19: 18 | D19: 18 | E19: 2855 | G19: 18 | J19: 18 | M19: 18 | P19: 18 | S19: 18 | V19: 18 | Y19: 18 | AB19: 18 | AE19: 18 | AH19: 18
A20: 19 | D20: 19 | E20: 570 | G20: 19 | H20: 3010 | J20: 19 | M20: 19 | P20: 19 | S20: 19 | V20: 19 | Y20: 19 | AB20: 19 | AE20: 19 | AH20: 19
A21: 20 | B21: -455 | D21: 20 | E21: -1480 | G21: 20 | H21: -260 | J21: 20 | M21: 20 | P21: 20 | S21: 20 | V21: 20 | Y21: 20 | AB21: 20 | AE21: 20 | AH21: 20
A22: 21 | B22: -8230 | D22: 21 | G22: 21 | J22: 21 | M22: 21 | P22: 21 | S22: 21 | V22: 21 | Y22: 21 | AB22: 21 | AE22: 21 | AH22: 21
A23: 22 | B23: -140 | D23: 22 | G23: 22 | J23: 22 | M23: 22 | P23: 22 | S23: 22 | V23: 22 | Y23: 22 | AB23: 22 | AE23: 22 | AH23: 22
A24: 23 | B24: -1120 | D24: 23 | E24: 1500 | G24: 23 | H24: 1365 | J24: 23 | M24: 23 | P24: 23 | S24: 23 | V24: 23 | Y24: 23 | AB24: 23 | AE24: 23 | AH24: 23
A25: 24 | D25: 24 | E25: -80 | G25: 24 | H25: 1495 | J25: 24 | M25: 24 | P25: 24 | S25: 24 | V25: 24 | Y25: 24 | AB25: 24 | AE25: 24 | AH25: 24
A26: 25 | D26: 25 | E26: 813 | G26: 25 | H26: -1580 | J26: 25 | M26: 25 | P26: 25 | S26: 25 | V26: 25 | Y26: 25 | AB26: 25 | AE26: 25 | AH26: 25
A27: 26 | B27: 3455 | D27: 26 | G27: 26 | H27: 362 | J27: 26 | M27: 26 | P27: 26 | S27: 26 | V27: 26 | Y27: 26 | AB27: 26 | AE27: 26 | AH27: 26
A28: 27 | B28: 1770 | D28: 27 | G28: 27 | H28: -20 | J28: 27 | M28: 27 | P28: 27 | S28: 27 | V28: 27 | Y28: 27 | AB28: 27 | AE28: 27 | AH28: 27
A29: 28 | D29: 28 | G29: 28 | J29: 28 | M29: 28 | P29: 28 | S29: 28 | V29: 28 | Y29: 28 | AB29: 28 | AE29: 28 | AH29: 28
A30: 29 | D30: 29 | G30: 29 | J30: 29 | M30: 29 | P30: 29 | S30: 29 | V30: 29 | Y30: 29 | AB30: 29 | AE30: 29 | AH30: 29
A31: 30 | B31: -450 | D31: 30 | G31: 30 | H31: 2365 | J31: 30 | M31: 30 | P31: 30 | S31: 30 | V31: 30 | Y31: 30 | AB31: 30 | AE31: 30 | AH31: 30
A32: 31 | D32: 31 | G32: 31 | H32: 30 | J32: 31 | M32: 31 | P32: 31 | S32: 31 | V32: 31 | Y32: 31 | AB32: 31 | AE32: 31 | AH32: 31
A35: Total | B35: =SUM(B2:B34) | E35: =SUM(E2:E27) | H35: =SUM(H2:H34) | K35: =SUM(K2:K34) | N35: =SUM(N2:N34) | Q35: =SUM(Q2:Q34) | T35: =SUM(T2:T34) | W35: =SUM(W2:W34) | Z35: =SUM(Z2:Z34) | AC35: =SUM(AC2:AC34) | AF35: =SUM(AF2:AF34) | AI35: =SUM(AI2:AI34)

Sheet BIC $3
A1: January | D1: February | G1: March | J1: April | M1: May | P1: Jun | S1: Jul | V1: Aug | Y1: Sep | AB1: Oct | AE1: Nov | AH1: Dec
A2: 1 | D2: 1 | G2: 1 | J2: 1 | M2: 1 | P2: 1 | S2: 1 | V2: 1 | Y2: 1 | AB2: 1 | AE2: 1 | AH2: 1
A3: 2 | D3: 2 | G3: 2 | H3: 735 | J3: 2 | M3: 2 | P3: 2 | S3: 2 | V3: 2 | Y3: 2 | AB3: 2 | AE3: 2 | AH3: 2
A4: 3 | D4: 3 | G4: 3 | H4: =-200-450 | J4: 3 | M4: 3 | P4: 3 | S4: 3 | V4: 3 | Y4: 3 | AB4: 3 | AE4: 3 | AH4: 3
A5: 4 | D5: 4 | G5: 4 | H5: -630 | J5: 4 | M5: 4 | P5: 4 | S5: 4 | V5: 4 | Y5: 4 | AB5: 4 | AE5: 4 | AH5: 4
A6: 5 | D6: 5 | G6: 5 | H6: -70 | J6: 5 | M6: 5 | P6: 5 | S6: 5 | V6: 5 | Y6: 5 | AB6: 5 | AE6: 5 | AH6: 5
A7: 6 | D7: 6 | G7: 6 | J7: 6 | M7: 6 | P7: 6 | S7: 6 | V7: 6 | Y7: 6 | AB7: 6 | AE7: 6 | AH7: 6
A8: 7 | D8: 7 | G8: 7 | J8: 7 | M8: 7 | P8: 7 | S8: 7 | V8: 7 | Y8: 7 | AB8: 7 | AE8: 7 | AH8: 7
A9: 8 | D9: 8 | G9: 8 | J9: 8 | M9: 8 | P9: 8 | S9: 8 | V9: 8 | Y9: 8 | AB9: 8 | AE9: 8 | AH9: 8
A10: 9 | D10: 9 | G10: 9 | H10: =-1250-1480 | J10: 9 | M10: 9 | P10: 9 | S10: 9 | V10: 9 | Y10: 9 | AB10: 9 | AE10: 9 | AH10: 9
A11: 10 | D11: 10 | G11: 10 | J11: 10 | M11: 10 | P11: 10 | S11: 10 | V11: 10 | Y11: 10 | AB11: 10 | AE11: 10 | AH11: 10
A12: 11 | D12: 11 | E12: -710 | G12: 11 | J12: 11 | M12: 11 | P12: 11 | S12: 11 | V12: 11 | Y12: 11 | AB12: 11 | AE12: 11 | AH12: 11
A13: 12 | D13: 12 | E13: 130 | G13: 12 | H13: =-85-650 | J13: 12 | M13: 12 | P13: 12 | S13: 12 | V13: 12 | Y13: 12 | AB13: 12 | AE13: 12 | AH13: 12
A14: 13 | D14: 13 | G14: 13 | H14: -50 | J14: 13 | M14: 13 | P14: 13 | S14: 13 | V14: 13 | Y14: 13 | AB14: 13 | AE14: 13 | AH14: 13
A15: 14 | D15: 14 | G15: 14 | J15: 14 | M15: 14 | P15: 14 | S15: 14 | V15: 14 | Y15: 14 | AB15: 14 | AE15: 14 | AH15: 14
A16: 15 | B16: 80 | D16: 15 | G16: 15 | J16: 15 | M16: 15 | P16: 15 | S16: 15 | V16: 15 | Y16: 15 | AB16: 15 | AE16: 15 | AH16: 15
A17: 16 | B17: -40 | D17: 16 | G17: 16 | H17: =2642+3845 | J17: 16 | M17: 16 | P17: 16 | S17: 16 | V17: 16 | Y17: 16 | AB17: 16 | AE17: 16 | AH17: 16
A18: 17 | D18: 17 | G18: 17 | H18: =3070+1065 | J18: 17 | M18: 17 | P18: 17 | S18: 17 | V18: 17 | Y18: 17 | AB18: 17 | AE18: 17 | AH18: 17
A19: 18 | D19: 18 | E19: 210 | G19: 18 | J19: 18 | M19: 18 | P19: 18 | S19: 18 | V19: 18 | Y19: 18 | AB19: 18 | AE19: 18 | AH19: 18
A20: 19 | D20: 19 | G20: 19 | H20: =2498+2820 | J20: 19 | M20: 19 | P20: 19 | S20: 19 | V20: 19 | Y20: 19 | AB20: 19 | AE20: 19 | AH20: 19
A21: 20 | B21: 50 | D21: 20 | E21: =-120+1125 | G21: 20 | H21: =-1715-1465 | J21: 20 | M21: 20 | P21: 20 | S21: 20 | V21: 20 | Y21: 20 | AB21: 20 | AE21: 20 | AH21: 20
A22: 21 | B22: -105 | D22: 21 | G22: 21 | J22: 21 | M22: 21 | P22: 21 | S22: 21 | V22: 21 | Y22: 21 | AB22: 21 | AE22: 21 | AH22: 21
A23: 22 | D23: 22 | G23: 22 | J23: 22 | M23: 22 | P23: 22 | S23: 22 | V23: 22 | Y23: 22 | AB23: 22 | AE23: 22 | AH23: 22
A24: 23 | D24: 23 | E24: 490 | G24: 23 | H24: =-1970-2045 | J24: 23 | M24: 23 | P24: 23 | S24: 23 | V24: 23 | Y24: 23 | AB24: 23 | AE24: 23 | AH24: 23
A25: 24 | D25: 24 | E25: =-335+490 | G25: 24 | H25: =-245+2230 | J25: 24 | M25: 24 | P25: 24 | S25: 24 | V25: 24 | Y25: 24 | AB25: 24 | AE25: 24 | AH25: 24
A26: 25 | D26: 25 | G26: 25 | H26: =1300-690 | J26: 25 | M26: 25 | P26: 25 | S26: 25 | V26: 25 | Y26: 25 | AB26: 25 | AE26: 25 | AH26: 25
A27: 26 | D27: 26 | G27: 26 | H27: =3100+2797 | J27: 26 | M27: 26 | P27: 26 | S27: 26 | V27: 26 | Y27: 26 | AB27: 26 | AE27: 26 | AH27: 26
A28: 27 | D28: 27 | E28: -790 | G28: 27 | H28: =745+3345 | J28: 27 | M28: 27 | P28: 27 | S28: 27 | V28: 27 | Y28: 27 | AB28: 27 | AE28: 27 | AH28: 27
A29: 28 | D29: 28 | G29: 28 | J29: 28 | M29: 28 | P29: 28 | S29: 28 | V29: 28 | Y29: 28 | AB29: 28 | AE29: 28 | AH29: 28
A30: 29 | D30: 29 | G30: 29 | J30: 29 | M30: 29 | P30: 29 | S30: 29 | V30: 29 | Y30: 29 | AB30: 29 | AE30: 29 | AH30: 29
A31: 30 | D31: 30 | G31: 30 | J31: 30 | M31: 30 | P31: 30 | S31: 30 | V31: 30 | Y31: 30 | AB31: 30 | AE31: 30 | AH31: 30
A32: 31 | D32: 31 | G32: 31 | H32: 770 | J32: 31 | M32: 31 | P32: 31 | S32: 31 | V32: 31 | Y32: 31 | AB32: 31 | AE32: 31 | AH32: 31
A35: Total | B35: =SUM(B2:B34) | E35: =SUM(E2:E27) | H35: =SUM(H2:H34) | K35: =SUM(K2:K34) | N35: =SUM(N2:N34) | Q35: =SUM(Q2:Q34) | T35: =SUM(T2:T34) | W35: =SUM(W2:W34) | Z35: =SUM(Z2:Z34) | AC35: =SUM(AC2:AC34) | AF35: =SUM(AF2:AF34) | AI35: =SUM(AI2:AI34)

Sheet BIC 1 DTE
A1: January | D1: February | G1: March | J1: April | M1: May | P1: Jun | S1: Jul | V1: Aug | Y1: Sep | AB1: Oct | AE1: Nov | AH1: Dec
A2: 1 | D2: 1 | G2: 1 | J2: 1 | M2: 1 | P2: 1 | S2: 1 | V2: 1 | Y2: 1 | AB2: 1 | AE2: 1 | AH2: 1
A3: 2 | D3: 2 | E3: 1525 | G3: 2 | H3: 795 | J3: 2 | M3: 2 | P3: 2 | S3: 2 | V3: 2 | Y3: 2 | AB3: 2 | AE3: 2 | AH3: 2
A4: 3 | D4: 3 | G4: 3 | J4: 3 | M4: 3 | P4: 3 | S4: 3 | V4: 3 | Y4: 3 | AB4: 3 | AE4: 3 | AH4: 3
A5: 4 | D5: 4 | G5: 4 | J5: 4 | M5: 4 | P5: 4 | S5: 4 | V5: 4 | Y5: 4 | AB5: 4 | AE5: 4 | AH5: 4
A6: 5 | B6: 170 | D6: 5 | G6: 5 | J6: 5 | M6: 5 | P6: 5 | S6: 5 | V6: 5 | Y6: 5 | AB6: 5 | AE6: 5 | AH6: 5
A7: 6 | D7: 6 | G7: 6 | J7: 6 | M7: 6 | P7: 6 | S7: 6 | V7: 6 | Y7: 6 | AB7: 6 | AE7: 6 | AH7: 6
A8: 7 | D8: 7 | G8: 7 | J8: 7 | M8: 7 | P8: 7 | S8: 7 | V8: 7 | Y8: 7 | AB8: 7 | AE8: 7 | AH8: 7
A9: 8 | D9: 8 | G9: 8 | J9: 8 | M9: 8 | P9: 8 | S9: 8 | V9: 8 | Y9: 8 | AB9: 8 | AE9: 8 | AH9: 8
A10: 9 | D10: 9 | E10: 255 | G10: 9 | H10: 1805 | J10: 9 | M10: 9 | P10: 9 | S10: 9 | V10: 9 | Y10: 9 | AB10: 9 | AE10: 9 | AH10: 9
A11: 10 | D11: 10 | G11: 10 | J11: 10 | M11: 10 | P11: 10 | S11: 10 | V11: 10 | Y11: 10 | AB11: 10 | AE11: 10 | AH11: 10
A12: 11 | D12: 11 | G12: 11 | J12: 11 | M12: 11 | P12: 11 | S12: 11 | V12: 11 | Y12: 11 | AB12: 11 | AE12: 11 | AH12: 11
A13: 12 | B13: 840 | D13: 12 | G13: 12 | J13: 12 | M13: 12 | P13: 12 | S13: 12 | V13: 12 | Y13: 12 | AB13: 12 | AE13: 12 | AH13: 12
A14: 13 | D14: 13 | G14: 13 | J14: 13 | M14: 13 | P14: 13 | S14: 13 | V14: 13 | Y14: 13 | AB14: 13 | AE14: 13 | AH14: 13
A15: 14 | D15: 14 | G15: 14 | J15: 14 | M15: 14 | P15: 14 | S15: 14 | V15: 14 | Y15: 14 | AB15: 14 | AE15: 14 | AH15: 14
A16: 15 | D16: 15 | G16: 15 | J16: 15 | M16: 15 | P16: 15 | S16: 15 | V16: 15 | Y16: 15 | AB16: 15 | AE16: 15 | AH16: 15
A17: 16 | D17: 16 | G17: 16 | H17: 1900 | J17: 16 | M17: 16 | P17: 16 | S17: 16 | V17: 16 | Y17: 16 | AB17: 16 | AE17: 16 | AH17: 16
A18: 17 | D18: 17 | G18: 17 | J18: 17 | M18: 17 | P18: 17 | S18: 17 | V18: 17 | Y18: 17 | AB18: 17 | AE18: 17 | AH18: 17
A19: 18 | D19: 18 | G19: 18 | J19: 18 | M19: 18 | P19: 18 | S19: 18 | V19: 18 | Y19: 18 | AB19: 18 | AE19: 18 | AH19: 18
A20: 19 | D20: 19 | G20: 19 | J20: 19 | M20: 19 | P20: 19 | S20: 19 | V20: 19 | Y20: 19 | AB20: 19 | AE20: 19 | AH20: 19
A21: 20 | D21: 20 | G21: 20 | J21: 20 | M21: 20 | P21: 20 | S21: 20 | V21: 20 | Y21: 20 | AB21: 20 | AE21: 20 | AH21: 20
A22: 21 | D22: 21 | G22: 21 | J22: 21 | M22: 21 | P22: 21 | S22: 21 | V22: 21 | Y22: 21 | AB22: 21 | AE22: 21 | AH22: 21
A23: 22 | D23: 22 | G23: 22 | J23: 22 | M23: 22 | P23: 22 | S23: 22 | V23: 22 | Y23: 22 | AB23: 22 | AE23: 22 | AH23: 22
A24: 23 | D24: 23 | E24: 3830 | G24: 23 | H24: -2755 | J24: 23 | M24: 23 | P24: 23 | S24: 23 | V24: 23 | Y24: 23 | AB24: 23 | AE24: 23 | AH24: 23
A25: 24 | D25: 24 | G25: 24 | J25: 24 | M25: 24 | P25: 24 | S25: 24 | V25: 24 | Y25: 24 | AB25: 24 | AE25: 24 | AH25: 24
A26: 25 | D26: 25 | G26: 25 | J26: 25 | M26: 25 | P26: 25 | S26: 25 | V26: 25 | Y26: 25 | AB26: 25 | AE26: 25 | AH26: 25
A27: 26 | B27: 540 | D27: 26 | G27: 26 | J27: 26 | M27: 26 | P27: 26 | S27: 26 | V27: 26 | Y27: 26 | AB27: 26 | AE27: 26 | AH27: 26
A28: 27 | D28: 27 | G28: 27 | J28: 27 | M28: 27 | P28: 27 | S28: 27 | V28: 27 | Y28: 27 | AB28: 27 | AE28: 27 | AH28: 27
A29: 28 | D29: 28 | G29: 28 | J29: 28 | M29: 28 | P29: 28 | S29: 28 | V29: 28 | Y29: 28 | AB29: 28 | AE29: 28 | AH29: 28
A30: 29 | D30: 29 | G30: 29 | J30: 29 | M30: 29 | P30: 29 | S30: 29 | V30: 29 | Y30: 29 | AB30: 29 | AE30: 29 | AH30: 29
A31: 30 | D31: 30 | G31: 30 | H31: -2780 | J31: 30 | M31: 30 | P31: 30 | S31: 30 | V31: 30 | Y31: 30 | AB31: 30 | AE31: 30 | AH31: 30
A32: 31 | D32: 31 | G32: 31 | J32: 31 | M32: 31 | P32: 31 | S32: 31 | V32: 31 | Y32: 31 | AB32: 31 | AE32: 31 | AH32: 31
A35: Total | B35: =SUM(B2:B34) | E35: =SUM(E2:E27) | H35: =SUM(H2:H34) | K35: =SUM(K2:K34) | N35: =SUM(N2:N34) | Q35: =SUM(Q2:Q34) | T35: =SUM(T2:T34) | W35: =SUM(W2:W34) | Z35: =SUM(Z2:Z34) | AC35: =SUM(AC2:AC34) | AF35: =SUM(AF2:AF34) | AI35: =SUM(AI2:AI34)

Sheet All BICs
A1: January | D1: February | G1: Mar | J1: April | M1: May | P1: Jun | S1: Jul | V1: Aug | Y1: Sep | AB1: Oct | AE1: Nov | AH1: Dec
A2: 1 | D2: 1 | G2: 1 | J2: 1 | M2: 1 | N2: ='BIC $6 $4'!N2+'BIC $4 '!N2+'BIC $3'!N2+'BIC 1 DTE'!N2 | P2: 1 | Q2: ='BIC $6 $4'!Q2+'BIC $4 '!Q2+'BIC $3'!Q2+'BIC 1 DTE'!Q2 | S2: 1 | T2: ='BIC $6 $4'!T2+'BIC $4 '!T2+'BIC $3'!T2+'BIC 1 DTE'!T2 | V2: 1 | W2: ='BIC $6 $4'!W2+'BIC $4 '!W2+'BIC $3'!W2+'BIC 1 DTE'!W2 | Y2: 1 | AB2: 1 | AC2: ='BIC $6 $4'!AC2+'BIC $4 '!AC2+'BIC $3'!AC2+'BIC 1 DTE'!AC2 | AE2: 1 | AH2: 1 | AI2: ='BIC $6 $4'!AI2+'BIC $4 '!AI2+'BIC $3'!AI2+'BIC 1 DTE'!AI2
A3: 2 | B3: ='BIC $6 $4'!B3+'BIC $4 '!B3+'BIC $3'!B3+'BIC 1 DTE'!B3 | D3: 2 | E3: ='BIC $6 $4'!E3+'BIC $4 '!E3+'BIC $3'!E3+'BIC 1 DTE'!E3 | G3: 2 | H3: ='BIC $6 $4'!H3+'BIC $4 '!H3+'BIC $3'!H3+'BIC 1 DTE'!H3+'BIC Standard'!H3 | J3: 2 | M3: 2 | N3: ='BIC $6 $4'!N3+'BIC $4 '!N3+'BIC $3'!N3+'BIC 1 DTE'!N3 | P3: 2 | Q3: ='BIC $6 $4'!Q3+'BIC $4 '!Q3+'BIC $3'!Q3+'BIC 1 DTE'!Q3 | S3: 2 | T3: ='BIC $6 $4'!T3+'BIC $4 '!T3+'BIC $3'!T3+'BIC 1 DTE'!T3 | V3: 2 | W3: ='BIC $6 $4'!W3+'BIC $4 '!W3+'BIC $3'!W3+'BIC 1 DTE'!W3 | Y3: 2 | Z3: ='BIC $6 $4'!Z3+'BIC $4 '!Z3+'BIC $3'!Z3+'BIC 1 DTE'!Z3 | AB3: 2 | AC3: ='BIC $6 $4'!AC3+'BIC $4 '!AC3+'BIC $3'!AC3+'BIC 1 DTE'!AC3 | AE3: 2 | AH3: 2 | AI3: ='BIC $6 $4'!AI3+'BIC $4 '!AI3+'BIC $3'!AI3+'BIC 1 DTE'!AI3
A4: 3 | D4: 3 | E4: ='BIC $6 $4'!E4+'BIC $4 '!E4+'BIC $3'!E4+'BIC 1 DTE'!E4 | G4: 3 | H4: ='BIC $6 $4'!H4+'BIC $4 '!H4+'BIC $3'!H4+'BIC 1 DTE'!H4+'BIC Standard'!H4 | J4: 3 | M4: 3 | P4: 3 | Q4: ='BIC $6 $4'!Q4+'BIC $4 '!Q4+'BIC $3'!Q4+'BIC 1 DTE'!Q4 | S4: 3 | T4: ='BIC $6 $4'!T4+'BIC $4 '!T4+'BIC $3'!T4+'BIC 1 DTE'!T4 | V4: 3 | Y4: 3 | Z4: ='BIC $6 $4'!Z4+'BIC $4 '!Z4+'BIC $3'!Z4+'BIC 1 DTE'!Z4 | AB4: 3 | AC4: ='BIC $6 $4'!AC4+'BIC $4 '!AC4+'BIC $3'!AC4+'BIC 1 DTE'!AC4 | AE4: 3 | AF4: ='BIC $6 $4'!AF4+'BIC $4 '!AF4+'BIC $3'!AF4+'BIC 1 DTE'!AF4 | AH4: 3 | AI4: ='BIC $6 $4'!AI4+'BIC $4 '!AI4+'BIC $3'!AI4+'BIC 1 DTE'!AI4
A5: 4 | D5: 4 | E5: ='BIC $6 $4'!E5+'BIC $4 '!E5+'BIC $3'!E5+'BIC 1 DTE'!E5 | G5: 4 | H5: ='BIC $6 $4'!H5+'BIC $4 '!H5+'BIC $3'!H5+'BIC 1 DTE'!H5+'BIC Standard'!H5 | J5: 4 | M5: 4 | P5: 4 | Q5: ='BIC $6 $4'!Q5+'BIC $4 '!Q5+'BIC $3'!Q5+'BIC 1 DTE'!Q5 | S5: 4 | V5: 4 | Y5: 4 | Z5: ='BIC $6 $4'!Z5+'BIC $4 '!Z5+'BIC $3'!Z5+'BIC 1 DTE'!Z5 | AB5: 4 | AE5: 4 | AF5: ='BIC $6 $4'!AF5+'BIC $4 '!AF5+'BIC $3'!AF5+'BIC 1 DTE'!AF5 | AH5: 4 | AI5: ='BIC $6 $4'!AI5+'BIC $4 '!AI5+'BIC $3'!AI5+'BIC 1 DTE'!AI5
A6: 5 | B6: ='BIC $6 $4'!B6+'BIC $4 '!B6+'BIC $3'!B6+'BIC 1 DTE'!B6 | D6: 5 | G6: 5 | H6: ='BIC $6 $4'!H6+'BIC $4 '!H6+'BIC $3'!H6+'BIC 1 DTE'!H6+'BIC Standard'!H6 | J6: 5 | M6: 5 | N6: ='BIC $6 $4'!N6+'BIC $4 '!N6+'BIC $3'!N6+'BIC 1 DTE'!N6 | P6: 5 | Q6: ='BIC $6 $4'!Q6+'BIC $4 '!Q6+'BIC $3'!Q6+'BIC 1 DTE'!Q6 | S6: 5 | V6: 5 | W6: ='BIC $6 $4'!W6+'BIC $4 '!W6+'BIC $3'!W6+'BIC 1 DTE'!W6 | Y6: 5 | Z6: ='BIC $6 $4'!Z6+'BIC $4 '!Z6+'BIC $3'!Z6+'BIC 1 DTE'!Z6 | AB6: 5 | AE6: 5 | AF6: ='BIC $6 $4'!AF6+'BIC $4 '!AF6+'BIC $3'!AF6+'BIC 1 DTE'!AF6 | AH6: 5 | AI6: ='BIC $6 $4'!AI6+'BIC $4 '!AI6+'BIC $3'!AI6+'BIC 1 DTE'!AI6
A7: 6 | B7: ='BIC $6 $4'!B7+'BIC $4 '!B7+'BIC $3'!B7+'BIC 1 DTE'!B7 | D7: 6 | E7: ='BIC $6 $4'!E7+'BIC $4 '!E7+'BIC $3'!E7+'BIC 1 DTE'!E7 | G7: 6 | H7: ='BIC $6 $4'!H7+'BIC $4 '!H7+'BIC $3'!H7+'BIC 1 DTE'!H7+'BIC Standard'!H7 | J7: 6 | M7: 6 | N7: ='BIC $6 $4'!N7+'BIC $4 '!N7+'BIC $3'!N7+'BIC 1 DTE'!N7 | P7: 6 | S7: 6 | V7: 6 | W7: ='BIC $6 $4'!W7+'BIC $4 '!W7+'BIC $3'!W7+'BIC 1 DTE'!W7 | Y7: 6 | AB7: 6 | AC7: ='BIC $6 $4'!AC7+'BIC $4 '!AC7+'BIC $3'!AC7+'BIC 1 DTE'!AC7 | AE7: 6 | AF7: ='BIC $6 $4'!AF7+'BIC $4 '!AF7+'BIC $3'!AF7+'BIC 1 DTE'!AF7 | AH7: 6
A8: 7 | B8: ='BIC $6 $4'!B8+'BIC $4 '!B8+'BIC $3'!B8+'BIC 1 DTE'!B8 | D8: 7 | G8: 7 | J8: 7 | M8: 7 | P8: 7 | S8: 7 | T8: ='BIC $6 $4'!T8+'BIC $4 '!T8+'BIC $3'!T8+'BIC 1 DTE'!T8 | V8: 7 | W8: ='BIC $6 $4'!W8+'BIC $4 '!W8+'BIC $3'!W8+'BIC 1 DTE'!W8 | Y8: 7 | AB8: 7 | AC8: ='BIC $6 $4'!AC8+'BIC $4 '!AC8+'BIC $3'!AC8+'BIC 1 DTE'!AC8 | AE8: 7 | AF8: ='BIC $6 $4'!AF8+'BIC $4 '!AF8+'BIC $3'!AF8+'BIC 1 DTE'!AF8 | AH8: 7
A9: 8 | B9: ='BIC $6 $4'!B9+'BIC $4 '!B9+'BIC $3'!B9+'BIC 1 DTE'!B9 | D9: 8 | G9: 8 | J9: 8 | M9: 8 | N9: ='BIC $6 $4'!N9+'BIC $4 '!N9+'BIC $3'!N9+'BIC 1 DTE'!N9 | P9: 8 | Q9: ='BIC $6 $4'!Q9+'BIC $4 '!Q9+'BIC $3'!Q9+'BIC 1 DTE'!Q9 | S9: 8 | T9: ='BIC $6 $4'!T9+'BIC $4 '!T9+'BIC $3'!T9+'BIC 1 DTE'!T9 | V9: 8 | W9: ='BIC $6 $4'!W9+'BIC $4 '!W9+'BIC $3'!W9+'BIC 1 DTE'!W9 | Y9: 8 | Z9: ='BIC $6 $4'!Z9+'BIC $4 '!Z9+'BIC $3'!Z9+'BIC 1 DTE'!Z9 | AB9: 8 | AE9: 8 | AH9: 8 | AI9: ='BIC $6 $4'!AI9+'BIC $4 '!AI9+'BIC $3'!AI9+'BIC 1 DTE'!AI9
A10: 9 | B10: ='BIC $6 $4'!B10+'BIC $4 '!B10+'BIC $3'!B10+'BIC 1 DTE'!B10 | D10: 9 | E10: ='BIC $6 $4'!E10+'BIC $4 '!E10+'BIC $3'!E10+'BIC 1 DTE'!E10 | G10: 9 | H10: ='BIC $6 $4'!H10+'BIC $4 '!H10+'BIC $3'!H10+'BIC 1 DTE'!H10+'BIC Standard'!H10 | J10: 9 | M10: 9 | N10: ='BIC $6 $4'!N10+'BIC $4 '!N10+'BIC $3'!N10+'BIC 1 DTE'!N10 | P10: 9 | Q10: ='BIC $6 $4'!Q10+'BIC $4 '!Q10+'BIC $3'!Q10+'BIC 1 DTE'!Q10 | S10: 9 | T10: ='BIC $6 $4'!T10+'BIC $4 '!T10+'BIC $3'!T10+'BIC 1 DTE'!T10 | V10: 9 | Y10: 9 | Z10: ='BIC $6 $4'!Z10+'BIC $4 '!Z10+'BIC $3'!Z10+'BIC 1 DTE'!Z10 | AB10: 9 | AC10: ='BIC $6 $4'!AC10+'BIC $4 '!AC10+'BIC $3'!AC10+'BIC 1 DTE'!AC10 | AE10: 9 | AH10: 9 | AI10: ='BIC $6 $4'!AI10+'BIC $4 '!AI10+'BIC $3'!AI10+'BIC 1 DTE'!AI10
A11: 10 | D11: 10 | E11: ='BIC $6 $4'!E11+'BIC $4 '!E11+'BIC $3'!E11+'BIC 1 DTE'!E11 | G11: 10 | H11: ='BIC $6 $4'!H11+'BIC $4 '!H11+'BIC $3'!H11+'BIC 1 DTE'!H11+'BIC Standard'!H11 | J11: 10 | M11: 10 | P11: 10 | Q11: ='BIC $6 $4'!Q11+'BIC $4 '!Q11+'BIC $3'!Q11+'BIC 1 DTE'!Q11 | S11: 10 | T11: ='BIC $6 $4'!T11+'BIC $4 '!T11+'BIC $3'!T11+'BIC 1 DTE'!T11 | V11: 10 | Y11: 10 | Z11: ='BIC $6 $4'!Z11+'BIC $4 '!Z11+'BIC $3'!Z11+'BIC 1 DTE'!Z11 | AB11: 10 | AC11: ='BIC $6 $4'!AC11+'BIC $4 '!AC11+'BIC $3'!AC11+'BIC 1 DTE'!AC11 | AE11: 10 | AF11: ='BIC $6 $4'!AF11+'BIC $4 '!AF11+'BIC $3'!AF11+'BIC 1 DTE'!AF11 | AH11: 10
A12: 11 | D12: 11 | E12: ='BIC $6 $4'!E12+'BIC $4 '!E12+'BIC $3'!E12+'BIC 1 DTE'!E12 | G12: 11 | H12: ='BIC $6 $4'!H12+'BIC $4 '!H12+'BIC $3'!H12+'BIC 1 DTE'!H12+'BIC Standard'!H12 | J12: 11 | M12: 11 | P12: 11 | Q12: ='BIC $6 $4'!Q12+'BIC $4 '!Q12+'BIC $3'!Q12+'BIC 1 DTE'!Q12 | S12: 11 | T12: ='BIC $6 $4'!T12+'BIC $4 '!T12+'BIC $3'!T12+'BIC 1 DTE'!T12 | V12: 11 | W12: ='BIC $6 $4'!W12+'BIC $4 '!W12+'BIC $3'!W12+'BIC 1 DTE'!W12 | Y12: 11 | Z12: ='BIC $6 $4'!Z12+'BIC $4 '!Z12+'BIC $3'!Z12+'BIC 1 DTE'!Z12 | AB12: 11 | AE12: 11 | AF12: ='BIC $6 $4'!AF12+'BIC $4 '!AF12+'BIC $3'!AF12+'BIC 1 DTE'!AF12 | AH12: 11 | AI12: ='BIC $6 $4'!AI12+'BIC $4 '!AI12+'BIC $3'!AI12+'BIC 1 DTE'!AI12
A13: 12 | B13: ='BIC $6 $4'!B13+'BIC $4 '!B13+'BIC $3'!B13+'BIC 1 DTE'!B13 | D13: 12 | E13: ='BIC $6 $4'!E13+'BIC $4 '!E13+'BIC $3'!E13+'BIC 1 DTE'!E13+'BIC Standard'!E13 | G13: 12 | H13: ='BIC $6 $4'!H13+'BIC $4 '!H13+'BIC $3'!H13+'BIC 1 DTE'!H13+'BIC Standard'!H13 | J13: 12 | M13: 12 | N13: ='BIC $6 $4'!N13+'BIC $4 '!N13+'BIC $3'!N13+'BIC 1 DTE'!N13 | P13: 12 | Q13: ='BIC $6 $4'!Q13+'BIC $4 '!Q13+'BIC $3'!Q13+'BIC 1 DTE'!Q13 | S13: 12 | V13: 12 | W13: ='BIC $6 $4'!W13+'BIC $4 '!W13+'BIC $3'!W13+'BIC 1 DTE'!W13 | Y13: 12 | Z13: ='BIC $6 $4'!Z13+'BIC $4 '!Z13+'BIC $3'!Z13+'BIC 1 DTE'!Z13 | AB13: 12 | AE13: 12 | AF13: ='BIC $6 $4'!AF13+'BIC $4 '!AF14+'BIC $3'!AF13+'BIC 1 DTE'!AF13 | AH13: 12 | AI13: ='BIC $6 $4'!AI13+'BIC $4 '!AI13+'BIC $3'!AI13+'BIC 1 DTE'!AI13
A14: 13 | B14: ='BIC $6 $4'!B14+'BIC $4 '!B14+'BIC $3'!B14+'BIC 1 DTE'!B14 | D14: 13 | E14: ='BIC $6 $4'!E14+'BIC $4 '!E14+'BIC $3'!E14+'BIC 1 DTE'!E14+'BIC Standard'!E14 | G14: 13 | H14: ='BIC $6 $4'!H14+'BIC $4 '!H14+'BIC $3'!H14+'BIC 1 DTE'!H14+'BIC Standard'!H14 | J14: 13 | M14: 13 | N14: ='BIC $6 $4'!N14+'BIC $4 '!N14+'BIC $3'!N14+'BIC 1 DTE'!N14 | P14: 13 | S14: 13 | V14: 13 | W14: ='BIC $6 $4'!W14+'BIC $4 '!W14+'BIC $3'!W14+'BIC 1 DTE'!W14 | Y14: 13 | AB14: 13 | AC14: ='BIC $6 $4'!AC14+'BIC $4 '!AC14+'BIC $3'!AC14+'BIC 1 DTE'!AC14 | AE14: 13 | AF14: ='BIC $6 $4'!AF14+'BIC $4 '!AF14+'BIC $3'!AF14+'BIC 1 DTE'!AF14 | AH14: 13
A15: 14 | B15: ='BIC $6 $4'!B15+'BIC $4 '!B15+'BIC $3'!B15+'BIC 1 DTE'!B15 | D15: 14 | G15: 14 | J15: 14 | M15: 14 | N15: ='BIC $6 $4'!N15+'BIC $4 '!N15+'BIC $3'!N15+'BIC 1 DTE'!N15 | P15: 14 | S15: 14 | T15: ='BIC $6 $4'!T15+'BIC $4 '!T15+'BIC $3'!T15+'BIC 1 DTE'!T15 | V15: 14 | W15: ='BIC $6 $4'!W15+'BIC $4 '!W15+'BIC $3'!W15+'BIC 1 DTE'!W15 | Y15: 14 | AB15: 14 | AC15: ='BIC $6 $4'!AC15+'BIC $4 '!AC15+'BIC $3'!AC15+'BIC 1 DTE'!AC15 | AE15: 14 | AF15: ='BIC $6 $4'!AF15+'BIC $4 '!AF15+'BIC $3'!AF15+'BIC 1 DTE'!AF15 | AH15: 14
A16: 15 | B16: ='BIC $6 $4'!B16+'BIC $4 '!B16+'BIC $3'!B16+'BIC 1 DTE'!B16 | D16: 15 | G16: 15 | J16: 15 | M16: 15 | N16: ='BIC $6 $4'!N16+'BIC $4 '!N16+'BIC $3'!N16+'BIC 1 DTE'!N16 | P16: 15 | Q16: ='BIC $6 $4'!Q16+'BIC $4 '!Q16+'BIC $3'!Q16+'BIC 1 DTE'!Q16 | S16: 15 | T16: ='BIC $6 $4'!T16+'BIC $4 '!T16+'BIC $3'!T16+'BIC 1 DTE'!T16 | V16: 15 | W16: ='BIC $6 $4'!W16+'BIC $4 '!W16+'BIC $3'!W16+'BIC 1 DTE'!W16 | Y16: 15 | Z16: ='BIC $6 $4'!Z16+'BIC $4 '!Z16+'BIC $3'!Z16+'BIC 1 DTE'!Z16 | AB16: 15 | AC16: ='BIC $6 $4'!AC16+'BIC $4 '!AC16+'BIC $3'!AC16+'BIC 1 DTE'!AC16 | AE16: 15 | AH16: 15 | AI16: ='BIC $6 $4'!AI16+'BIC $4 '!AI16+'BIC $3'!AI16+'BIC 1 DTE'!AI16
A17: 16 | B17: ='BIC $6 $4'!B17+'BIC $4 '!B17+'BIC $3'!B17+'BIC 1 DTE'!B17 | D17: 16 | G17: 16 | H17: ='BIC $6 $4'!H17+'BIC $4 '!H17+'BIC $3'!H17+'BIC 1 DTE'!H17+'BIC Standard'!H17 | J17: 16 | M17: 16 | N17: ='BIC $6 $4'!N17+'BIC $4 '!N17+'BIC $3'!N17+'BIC 1 DTE'!N17 | P17: 16 | Q17: ='BIC $6 $4'!Q17+'BIC $4 '!Q17+'BIC $3'!Q17+'BIC 1 DTE'!Q17 | S17: 16 | T17: ='BIC $6 $4'!T17+'BIC $4 '!T17+'BIC $3'!T17+'BIC 1 DTE'!T17 | V17: 16 | Y17: 16 | Z17: ='BIC $6 $4'!Z17+'BIC $4 '!Z17+'BIC $3'!Z17+'BIC 1 DTE'!Z17 | AB17: 16 | AC17: ='BIC $6 $4'!AC17+'BIC $4 '!AC17+'BIC $3'!AC17+'BIC 1 DTE'!AC17 | AE17: 16 | AH17: 16 | AI17: ='BIC $6 $4'!AI17+'BIC $4 '!AI17+'BIC $3'!AI17+'BIC 1 DTE'!AI17
A18: 17 | D18: 17 | E18: ='BIC $6 $4'!E18+'BIC $4 '!E18+'BIC $3'!E18+'BIC 1 DTE'!E18+'BIC Standard'!E18 | G18: 17 | H18: ='BIC $6 $4'!H18+'BIC $4 '!H18+'BIC $3'!H18+'BIC 1 DTE'!H18+'BIC Standard'!H18 | J18: 17 | M18: 17 | N18: ='BIC $6 $4'!N18+'BIC $4 '!N18+'BIC $3'!N18+'BIC 1 DTE'!N18 | P18: 17 | S18: 17 | T18: ='BIC $6 $4'!T18+'BIC $4 '!T18+'BIC $3'!T18+'BIC 1 DTE'!T18 | V18: 17 | Y18: 17 | AB18: 17 | AC18: ='BIC $6 $4'!AC18+'BIC $4 '!AC18+'BIC $3'!AC18+'BIC 1 DTE'!AC18 | AE18: 17 | AF18: ='BIC $6 $4'!AF18+'BIC $4 '!AF18+'BIC $3'!AF18+'BIC 1 DTE'!AF18 | AH18: 17 | AI18: ='BIC $6 $4'!AI18+'BIC $4 '!AI18+'BIC $3'!AI18+'BIC 1 DTE'!AI18
A19: 18 | D19: 18 | E19: ='BIC $6 $4'!E19+'BIC Standard'!E19+'BIC $4 '!E19+'BIC $3'!E19+'BIC 1 DTE'!E19 | G19: 18 | H19: ='BIC $6 $4'!H19+'BIC $4 '!H19+'BIC $3'!H19+'BIC 1 DTE'!H19+'BIC Standard'!H19 | J19: 18 | M19: 18 | N19: ='BIC $6 $4'!N19+'BIC $4 '!N19+'BIC $3'!N19+'BIC 1 DTE'!N19 | P19: 18 | S19: 18 | T19: ='BIC $6 $4'!T19+'BIC $4 '!T19+'BIC $3'!T19+'BIC 1 DTE'!T19 | V19: 18 | W19: ='BIC $6 $4'!W19+'BIC $4 '!W19+'BIC $3'!W19+'BIC 1 DTE'!W19 | Y19: 18 | Z19: ='BIC $6 $4'!Z19+'BIC $4 '!Z19+'BIC $3'!Z19+'BIC 1 DTE'!Z19 | AB19: 18 | AE19: 18 | AF19: ='BIC $6 $4'!AF19+'BIC $4 '!AF19+'BIC $3'!AF19+'BIC 1 DTE'!AF19 | AH19: 18 | AI19: ='BIC $6 $4'!AI19+'BIC $4 '!AI19+'BIC $3'!AI19+'BIC 1 DTE'!AI19
A20: 19 | D20: 19 | E20: ='BIC $6 $4'!E20+'BIC Standard'!E20+'BIC $4 '!E20+'BIC $3'!E20+'BIC 1 DTE'!E20 | G20: 19 | H20: ='BIC $6 $4'!H20+'BIC $4 '!H20+'BIC $3'!H20+'BIC 1 DTE'!H20+'BIC Standard'!H20 | J20: 19 | M20: 19 | P20: 19 | Q20: ='BIC $6 $4'!Q20+'BIC $4 '!Q20+'BIC $3'!Q20+'BIC 1 DTE'!Q20 | S20: 19 | V20: 19 | W20: ='BIC $6 $4'!W20+'BIC $4 '!W20+'BIC $3'!W20+'BIC 1 DTE'!W20 | Y20: 19 | Z20: ='BIC $6 $4'!Z20+'BIC $4 '!Z20+'BIC $3'!Z20+'BIC 1 DTE'!Z20 | AB20: 19 | AE20: 19 | AF20: ='BIC $6 $4'!AF20+'BIC $4 '!AF20+'BIC $3'!AF20+'BIC 1 DTE'!AF20 | AH20: 19 | AI20: ='BIC $6 $4'!AI20+'BIC $4 '!AI20+'BIC $3'!AI20+'BIC 1 DTE'!AI20
A21: 20 | B21: ='BIC $6 $4'!B21+'BIC $4 '!B21+'BIC $3'!B21+'BIC 1 DTE'!B21 | D21: 20 | E21: ='BIC $6 $4'!E21+'BIC Standard'!E21+'BIC $4 '!E21+'BIC $3'!E21+'BIC 1 DTE'!E21 | G21: 20 | H21: ='BIC $6 $4'!H21+'BIC $4 '!H21+'BIC $3'!H21+'BIC 1 DTE'!H21+'BIC Standard'!H21 | J21: 20 | M21: 20 | P21: 20 | S21: 20 | V21: 20 | W21: ='BIC $6 $4'!W21+'BIC $4 '!W21+'BIC $3'!W21+'BIC 1 DTE'!W21 | Y21: 20 | AB21: 20 | AC21: ='BIC $6 $4'!AC21+'BIC $4 '!AC21+'BIC $3'!AC21+'BIC 1 DTE'!AC21 | AE21: 20 | AF21: ='BIC $6 $4'!AF21+'BIC $4 '!AF21+'BIC $3'!AF21+'BIC 1 DTE'!AF21 | AH21: 20
A22: 21 | B22: ='BIC $6 $4'!B22+'BIC $4 '!B22+'BIC $3'!B22+'BIC 1 DTE'!B22 | D22: 21 | G22: 21 | J22: 21 | M22: 21 | N22: ='BIC $6 $4'!N22+'BIC $4 '!N22+'BIC $3'!N22+'BIC 1 DTE'!N22 | P22: 21 | S22: 21 | T22: ='BIC $6 $4'!T22+'BIC $4 '!T22+'BIC $3'!T22+'BIC 1 DTE'!T22 | V22: 21 | W22: ='BIC $6 $4'!W22+'BIC $4 '!W22+'BIC $3'!W22+'BIC 1 DTE'!W22 | Y22: 21 | AB22: 21 | AC22: ='BIC $6 $4'!AC22+'BIC $4 '!AC22+'BIC $3'!AC22+'BIC 1 DTE'!AC22 | AE22: 21 | AF22: ='BIC $6 $4'!AF22+'BIC $4 '!AF22+'BIC $3'!AF22+'BIC 1 DTE'!AF22 | AH22: 21
A23: 22 | B23: ='BIC $6 $4'!B23+'BIC $4 '!B23+'BIC $3'!B23+'BIC 1 DTE'!B23 | D23: 22 | G23: 22 | J23: 22 | M23: 22 | N23: ='BIC $6 $4'!N23+'BIC $4 '!N23+'BIC $3'!N23+'BIC 1 DTE'!N23 | P23: 22 | Q23: ='BIC $6 $4'!Q23+'BIC $4 '!Q23+'BIC $3'!Q23+'BIC 1 DTE'!Q23 | S23: 22 | T23: ='BIC $6 $4'!T23+'BIC $4 '!T23+'BIC $3'!T23+'BIC 1 DTE'!T23 | V23: 22 | W23: ='BIC $6 $4'!W23+'BIC $4 '!W23+'BIC $3'!W23+'BIC 1 DTE'!W23 | Y23: 22 | Z23: ='BIC $6 $4'!Z23+'BIC $4 '!Z23+'BIC $3'!Z23+'BIC 1 DTE'!Z23 | AB23: 22 | AC23: ='BIC $6 $4'!AC23+'BIC $4 '!AC23+'BIC $3'!AC23+'BIC 1 DTE'!AC23 | AE23: 22 | AH23: 22 | AI23: ='BIC $6 $4'!AI23+'BIC $4 '!AI23+'BIC $3'!AI23+'BIC 1 DTE'!AI23
A24: 23 | B24: ='BIC $6 $4'!B24+'BIC $4 '!B24+'BIC $3'!B24+'BIC 1 DTE'!B24 | D24: 23 | E24: ='BIC $6 $4'!E24+'BIC Standard'!E24+'BIC $4 '!E24+'BIC $3'!E24+'BIC 1 DTE'!E24 | G24: 23 | H24: ='BIC $6 $4'!H24+'BIC $4 '!H24+'BIC $3'!H24+'BIC 1 DTE'!H24+'BIC Standard'!H24 | J24: 23 | M24: 23 | N24: ='BIC $6 $4'!N24+'BIC $4 '!N24+'BIC $3'!N24+'BIC 1 DTE'!N24 | P24: 23 | Q24: ='BIC $6 $4'!Q24+'BIC $4 '!Q24+'BIC $3'!Q24+'BIC 1 DTE'!Q24 | S24: 23 | T24: ='BIC $6 $4'!T24+'BIC $4 '!T24+'BIC $3'!T24+'BIC 1 DTE'!T24 | V24: 23 | Y24: 23 | Z24: ='BIC $6 $4'!Z24+'BIC $4 '!Z24+'BIC $3'!Z24+'BIC 1 DTE'!Z24 | AB24: 23 | AC24: ='BIC $6 $4'!AC24+'BIC $4 '!AC24+'BIC $3'!AC24+'BIC 1 DTE'!AC24 | AE24: 23 | AH24: 23 | AI24: ='BIC $6 $4'!AI24+'BIC $4 '!AI24+'BIC $3'!AI24+'BIC 1 DTE'!AI24
A25: 24 | D25: 24 | E25: ='BIC $6 $4'!E25+'BIC Standard'!E25+'BIC $4 '!E25+'BIC $3'!E25+'BIC 1 DTE'!E25 | G25: 24 | H25: ='BIC $6 $4'!H25+'BIC $4 '!H25+'BIC $3'!H25+'BIC 1 DTE'!H25+'BIC Standard'!H25 | J25: 24 | M25: 24 | P25: 24 | Q25: ='BIC $6 $4'!Q25+'BIC $4 '!Q25+'BIC $3'!Q25+'BIC 1 DTE'!Q25 | S25: 24 | T25: ='BIC $6 $4'!T25+'BIC $4 '!T25+'BIC $3'!T25+'BIC 1 DTE'!T25 | V25: 24 | Y25: 24 | Z25: ='BIC $6 $4'!Z25+'BIC $4 '!Z25+'BIC $3'!Z25+'BIC 1 DTE'!Z25 | AB25: 24 | AC25: ='BIC $6 $4'!AC25+'BIC $4 '!AC25+'BIC $3'!AC25+'BIC 1 DTE'!AC25 | AE25: 24 | AF25: ='BIC $6 $4'!AF25+'BIC $4 '!AF25+'BIC $3'!AF25+'BIC 1 DTE'!AF25 | AH25: 24
A26: 25 | D26: 25 | E26: ='BIC $6 $4'!E26+'BIC Standard'!E26+'BIC $4 '!E26+'BIC $3'!E26+'BIC 1 DTE'!E26 | G26: 25 | H26: ='BIC $6 $4'!H26+'BIC $4 '!H26+'BIC $3'!H26+'BIC 1 DTE'!H26+'BIC Standard'!H26 | J26: 25 | M26: 25 | P26: 25 | Q26: ='BIC $6 $4'!Q26+'BIC $4 '!Q26+'BIC $3'!Q26+'BIC 1 DTE'!Q26 | S26: 25 | T26: ='BIC $6 $4'!T26+'BIC $4 '!T26+'BIC $3'!T26+'BIC 1 DTE'!T26 | V26: 25 | W26: ='BIC $6 $4'!W26+'BIC $4 '!W26+'BIC $3'!W26+'BIC 1 DTE'!W26 | Y26: 25 | Z26: ='BIC $6 $4'!Z26+'BIC $4 '!Z26+'BIC $3'!Z26+'BIC 1 DTE'!Z26 | AB26: 25 | AE26: 25 | AF26: ='BIC $6 $4'!AF26+'BIC $4 '!AF26+'BIC $3'!AF26+'BIC 1 DTE'!AF26 | AH26: 25
A27: 26 | B27: ='BIC $6 $4'!B27+'BIC $4 '!B27+'BIC $3'!B27+'BIC 1 DTE'!B27 | D27: 26 | E27: ='BIC $6 $4'!E27+'BIC Standard'!E27+'BIC $4 '!E27+'BIC $3'!E27+'BIC 1 DTE'!E27 | G27: 26 | H27: ='BIC $6 $4'!H27+'BIC $4 '!H27+'BIC $3'!H27+'BIC 1 DTE'!H27+'BIC Standard'!H27 | J27: 26 | M27: 26 | P27: 26 | Q27: ='BIC $6 $4'!Q27+'BIC $4 '!Q27+'BIC $3'!Q27+'BIC 1 DTE'!Q27 | S27: 26 | V27: 26 | W27: ='BIC $6 $4'!W27+'BIC $4 '!W27+'BIC $3'!W27+'BIC 1 DTE'!W27 | Y27: 26 | Z27: ='BIC $6 $4'!Z27+'BIC $4 '!Z27+'BIC $3'!Z27+'BIC 1 DTE'!Z27 | AB27: 26 | AE27: 26 | AF27: ='BIC $6 $4'!AF27+'BIC $4 '!AF27+'BIC $3'!AF27+'BIC 1 DTE'!AF27 | AH27: 26 | AI27: ='BIC $6 $4'!AI27+'BIC $4 '!AI27+'BIC $3'!AI27+'BIC 1 DTE'!AI27
A28: 27 | B28: ='BIC $6 $4'!B28+'BIC $4 '!B28+'BIC $3'!B28+'BIC 1 DTE'!B28 | D28: 27 | E28: ='BIC $6 $4'!E28+'BIC Standard'!E28+'BIC $4 '!E28+'BIC $3'!E28+'BIC 1 DTE'!E28 | G28: 27 | H28: ='BIC $6 $4'!H28+'BIC $4 '!H28+'BIC $3'!H28+'BIC 1 DTE'!H28+'BIC Standard'!H28 | J28: 27 | M28: 27 | N28: ='BIC $6 $4'!N28+'BIC $4 '!N28+'BIC $3'!N28+'BIC 1 DTE'!N28 | P28: 27 | S28: 27 | V28: 27 | W28: ='BIC $6 $4'!W28+'BIC $4 '!W28+'BIC $3'!W28+'BIC 1 DTE'!W28 | Y28: 27 | AB28: 27 | AC28: ='BIC $6 $4'!AC28+'BIC $4 '!AC28+'BIC $3'!AC28+'BIC 1 DTE'!AC28 | AE28: 27 | AH28: 27
A29: 28 | D29: 28 | G29: 28 | J29: 28 | M29: 28 | N29: ='BIC $6 $4'!N29+'BIC $4 '!N29+'BIC $3'!N29+'BIC 1 DTE'!N29 | P29: 28 | S29: 28 | T29: ='BIC $6 $4'!T29+'BIC $4 '!T29+'BIC $3'!T29+'BIC 1 DTE'!T29 | V29: 28 | W29: ='BIC $6 $4'!W29+'BIC $4 '!W29+'BIC $3'!W29+'BIC 1 DTE'!W29 | Y29: 28 | AB29: 28 | AC29: ='BIC $6 $4'!AC29+'BIC $4 '!AC29+'BIC $3'!AC29+'BIC 1 DTE'!AC29 | AE29: 28 | AF29: ='BIC $6 $4'!AF29+'BIC $4 '!AF29+'BIC $3'!AF29+'BIC 1 DTE'!AF29 | AH29: 28
A30: 29 | D30: 29 | G30: 29 | J30: 29 | M30: 29 | N30: ='BIC $6 $4'!N30+'BIC $4 '!N30+'BIC $3'!N30+'BIC 1 DTE'!N30 | P30: 29 | Q30: ='BIC $6 $4'!Q30+'BIC $4 '!Q30+'BIC $3'!Q30+'BIC 1 DTE'!Q30 | S30: 29 | T30: ='BIC $6 $4'!T30+'BIC $4 '!T30+'BIC $3'!T30+'BIC 1 DTE'!T30 | V30: 29 | W30: ='BIC $6 $4'!W30+'BIC $4 '!W30+'BIC $3'!W30+'BIC 1 DTE'!W30 | Y30: 29 | Z30: ='BIC $6 $4'!Z30+'BIC $4 '!Z30+'BIC $3'!Z30+'BIC 1 DTE'!Z30 | AB30: 29 | AE30: 29 | AH30: 29 | AI30: ='BIC $6 $4'!AI30+'BIC $4 '!AI30+'BIC $3'!AI30+'BIC 1 DTE'!AI30
A31: 30 | B31: ='BIC $6 $4'!B31+'BIC $4 '!B31+'BIC $3'!B31+'BIC 1 DTE'!B31 | D31: 30 | G31: 30 | H31: ='BIC $6 $4'!H31+'BIC $4 '!H31+'BIC $3'!H31+'BIC 1 DTE'!H31+'BIC Standard'!H31 | J31: 30 | M31: 30 | N31: ='BIC $6 $4'!N31+'BIC $4 '!N31+'BIC $3'!N31+'BIC 1 DTE'!N31 | P31: 30 | S31: 30 | V31: 30 | Y31: 30 | AB31: 30 | AC31: ='BIC $6 $4'!AC31+'BIC $4 '!AC31+'BIC $3'!AC31+'BIC 1 DTE'!AC31 | AE31: 30 | AH31: 30 | AI31: ='BIC $6 $4'!AI31+'BIC $4 '!AI31+'BIC $3'!AI31+'BIC 1 DTE'!AI31
A32: 31 | D32: 31 | G32: 31 | H32: ='BIC $6 $4'!H32+'BIC $4 '!H32+'BIC $3'!H32+'BIC 1 DTE'!H32+'BIC Standard'!H32 | J32: 31 | M32: 31 | P32: 31 | S32: 31 | V32: 31 | Y32: 31 | AB32: 31 | AC32: ='BIC $6 $4'!AC32+'BIC $4 '!AC32+'BIC $3'!AC32+'BIC 1 DTE'!AC32 | AE32: 31 | AH32: 31
A35: Total | B35: ='BIC $6 $4'!B35+'BIC $4 '!B35+'BIC $3'!B35+'BIC 1 DTE'!B35 | E35: =SUM(E2:E27) | H35: =SUM(H2:H32) | K35: ='BIC $6 $4'!K35+'BIC $4 '!K35+'BIC $3'!K35+'BIC 1 DTE'!K35 | N35: =SUM(N2:N34) | Q35: =SUM(Q2:Q34) | T35: =SUM(T2:T34) | W35: =SUM(W2:W34) | Z35: =SUM(Z2:Z34) | AC35: =SUM(AC2:AC34) | AF35: =SUM(AF2:AF34) | AI35: =SUM(AI2:AI34)

Sheet Price Action IC
A1: January | D1: February | G1: March | J1: April | M1: May | P1: Jun | S1: Jul | V1: Aug | Y1: Sep | AB1: Oct | AE1: Nov | AH1: Dec
A2: 1 | D2: 1 | G2: 1 | J2: 1 | M2: 1 | P2: 1 | S2: 1 | V2: 1 | Y2: 1 | AB2: 1 | AE2: 1 | AH2: 1
A3: 2 | B3: -2630 | D3: 2 | E3: 1205 | G3: 2 | J3: 2 | M3: 2 | P3: 2 | S3: 2 | V3: 2 | Y3: 2 | AB3: 2 | AE3: 2 | AH3: 2
A4: 3 | D4: 3 | E4: -5660 | G4: 3 | H4: -2390 | J4: 3 | M4: 3 | P4: 3 | S4: 3 | V4: 3 | Y4: 3 | AB4: 3 | AE4: 3 | AH4: 3
A5: 4 | D5: 4 | E5: -1480 | G5: 4 | H5: 2370 | J5: 4 | M5: 4 | P5: 4 | S5: 4 | V5: 4 | Y5: 4 | AB5: 4 | AE5: 4 | AH5: 4
A6: 5 | B6: -1300 | D6: 5 | E6: 920 | G6: 5 | H6: 5 | J6: 5 | M6: 5 | P6: 5 | S6: 5 | V6: 5 | Y6: 5 | AB6: 5 | AE6: 5 | AH6: 5
A7: 6 | B7: -1180 | D7: 6 | E7: 3095 | G7: 6 | H7: 3350 | J7: 6 | M7: 6 | P7: 6 | S7: 6 | V7: 6 | Y7: 6 | AB7: 6 | AE7: 6 | AH7: 6
A8: 7 | B8: -460 | D8: 7 | G8: 7 | J8: 7 | M8: 7 | P8: 7 | S8: 7 | V8: 7 | Y8: 7 | AB8: 7 | AE8: 7 | AH8: 7
A9: 8 | B9: 1930 | D9: 8 | G9: 8 | J9: 8 | M9: 8 | P9: 8 | S9: 8 | V9: 8 | Y9: 8 | AB9: 8 | AE9: 8 | AH9: 8
A10: 9 | B10: 5 | D10: 9 | E10: -330 | G10: 9 | H10: -80 | J10: 9 | M10: 9 | P10: 9 | S10: 9 | V10: 9 | Y10: 9 | AB10: 9 | AE10: 9 | AH10: 9
A11: 10 | D11: 10 | E11: 1350 | G11: 10 | H11: -675 | J11: 10 | M11: 10 | P11: 10 | S11: 10 | V11: 10 | Y11: 10 | AB11: 10 | AE11: 10 | AH11: 10
A12: 11 | D12: 11 | E12: 1610 | G12: 11 | H12: 2075 | J12: 11 | M12: 11 | P12: 11 | S12: 11 | V12: 11 | Y12: 11 | AB12: 11 | AE12: 11 | AH12: 11
A13: 12 | B13: 60 | D13: 12 | E13: -310 | G13: 12 | H13: 4275 | J13: 12 | M13: 12 | P13: 12 | S13: 12 | V13: 12 | Y13: 12 | AB13: 12 | AE13: 12 | AH13: 12
A14: 13 | B14: -1060 | D14: 13 | E14: 1110 | G14: 13 | H14: -1740 | J14: 13 | M14: 13 | P14: 13 | S14: 13 | V14: 13 | Y14: 13 | AB14: 13 | AE14: 13 | AH14: 13
A15: 14 | B15: -1305 | D15: 14 | G15: 14 | J15: 14 | M15: 14 | P15: 14 | S15: 14 | V15: 14 | Y15: 14 | AB15: 14 | AE15: 14 | AH15: 14
A16: 15 | B16: -820 | D16: 15 | G16: 15 | J16: 15 | M16: 15 | P16: 15 | S16: 15 | V16: 15 | Y16: 15 | AB16: 15 | AE16: 15 | AH16: 15
A17: 16 | B17: 320 | D17: 16 | G17: 16 | H17: -675 | J17: 16 | M17: 16 | P17: 16 | S17: 16 | V17: 16 | Y17: 16 | AB17: 16 | AE17: 16 | AH17: 16
A18: 17 | D18: 17 | E18: 65 | G18: 17 | H18: 2870 | J18: 17 | M18: 17 | P18: 17 | S18: 17 | V18: 17 | Y18: 17 | AB18: 17 | AE18: 17 | AH18: 17
A19: 18 | D19: 18 | E19: -10 | G19: 18 | H19: 465 | J19: 18 | M19: 18 | P19: 18 | S19: 18 | V19: 18 | Y19: 18 | AB19: 18 | AE19: 18 | AH19: 18
A20: 19 | D20: 19 | E20: 430 | G20: 19 | H20: 1825 | J20: 19 | M20: 19 | P20: 19 | S20: 19 | V20: 19 | Y20: 19 | AB20: 19 | AE20: 19 | AH20: 19
A21: 20 | B21: 975 | D21: 20 | E21: -340 | G21: 20 | H21: -3680 | J21: 20 | M21: 20 | P21: 20 | S21: 20 | V21: 20 | Y21: 20 | AB21: 20 | AE21: 20 | AH21: 20
A22: 21 | B22: -670 | D22: 21 | G22: 21 | J22: 21 | M22: 21 | P22: 21 | S22: 21 | V22: 21 | Y22: 21 | AB22: 21 | AE22: 21 | AH22: 21
A23: 22 | B23: 1200 | D23: 22 | G23: 22 | J23: 22 | M23: 22 | P23: 22 | S23: 22 | V23: 22 | Y23: 22 | AB23: 22 | AE23: 22 | AH23: 22
A24: 23 | B24: -1060 | D24: 23 | E24: 2560 | G24: 23 | H24: -2310 | J24: 23 | M24: 23 | P24: 23 | S24: 23 | V24: 23 | Y24: 23 | AB24: 23 | AE24: 23 | AH24: 23
A25: 24 | D25: 24 | E25: 1060 | G25: 24 | H25: -1265 | J25: 24 | M25: 24 | P25: 24 | S25: 24 | V25: 24 | Y25: 24 | AB25: 24 | AE25: 24 | AH25: 24
A26: 25 | D26: 25 | E26: 60 | G26: 25 | H26: 3190 | J26: 25 | M26: 25 | P26: 25 | S26: 25 | V26: 25 | Y26: 25 | AB26: 25 | AE26: 25 | AH26: 25
A27: 26 | B27: 1290 | D27: 26 | E27: 760 | G27: 26 | H27: 95 | J27: 26 | M27: 26 | P27: 26 | S27: 26 | V27: 26 | Y27: 26 | AB27: 26 | AE27: 26 | AH27: 26
A28: 27 | B28: 450 | D28: 27 | E28: 140 | G28: 27 | H28: -2810 | J28: 27 | M28: 27 | P28: 27 | S28: 27 | V28: 27 | Y28: 27 | AB28: 27 | AE28: 27 | AH28: 27
A29: 28 | D29: 28 | G29: 28 | J29: 28 | M29: 28 | P29: 28 | S29: 28 | V29: 28 | Y29: 28 | AB29: 28 | AE29: 28 | AH29: 28
A30: 29 | B30: 1100 | D30: 29 | G30: 29 | J30: 29 | M30: 29 | P30: 29 | S30: 29 | V30: 29 | Y30: 29 | AB30: 29 | AE30: 29 | AH30: 29
A31: 30 | B31: -2830 | D31: 30 | G31: 30 | H31: 1425 | J31: 30 | M31: 30 | P31: 30 | S31: 30 | V31: 30 | Y31: 30 | AB31: 30 | AE31: 30 | AH31: 30
A32: 31 | D32: 31 | G32: 31 | H32: 480 | J32: 31 | M32: 31 | P32: 31 | S32: 31 | V32: 31 | Y32: 31 | AB32: 31 | AE32: 31 | AH32: 31
A35: Total | B35: =SUM(B2:B34) | E35: =SUM(E2:E28) | H35: =SUM(H2:H34) | K35: =SUM(K2:K34) | N35: =SUM(N2:N34) | Q35: =SUM(Q2:Q34) | T35: =SUM(T2:T34) | W35: =SUM(W2:W34) | Z35: =SUM(Z2:Z34) | AC35: =SUM(AC2:AC34) | AF35: =SUM(AF2:AF34) | AI35: =SUM(AI2:AI34)

Sheet Verticals
A1: January | D1: February | G1: March | J1: April | M1: May | P1: Jun | S1: Jul | V1: Aug | Y1: Sep | AB1: Oct | AE1: Nov | AH1: Dec
A2: 1 | D2: 1 | G2: 1 | J2: 1 | M2: 1 | P2: 1 | S2: 1 | V2: 1 | Y2: 1 | AB2: 1 | AE2: 1 | AH2: 1
A3: 2 | B3: =-590-1300 | D3: 2 | E3: =795-235 | G3: 2 | H3: 1081 | J3: 2 | M3: 2 | P3: 2 | S3: 2 | V3: 2 | Y3: 2 | AB3: 2 | AE3: 2 | AH3: 2
A4: 3 | D4: 3 | E4: -385 | G4: 3 | H4: =-1240+7376 | J4: 3 | M4: 3 | P4: 3 | S4: 3 | V4: 3 | Y4: 3 | AB4: 3 | AE4: 3 | AH4: 3
A5: 4 | D5: 4 | E5: 1710 | G5: 4 | H5: 3350 | J5: 4 | M5: 4 | P5: 4 | S5: 4 | V5: 4 | Y5: 4 | AB5: 4 | AE5: 4 | AH5: 4
A6: 5 | B6: 570 | D6: 5 | E6: =-1600+1050 | G6: 5 | H6: =-2263-2845 | J6: 5 | M6: 5 | P6: 5 | S6: 5 | V6: 5 | Y6: 5 | AB6: 5 | AE6: 5 | AH6: 5
A7: 6 | B7: 1010 | D7: 6 | E7: 2850 | G7: 6 | H7: =-604-5158 | J7: 6 | M7: 6 | P7: 6 | S7: 6 | V7: 6 | Y7: 6 | AB7: 6 | AE7: 6 | AH7: 6
A8: 7 | B8: -2932 | D8: 7 | G8: 7 | J8: 7 | M8: 7 | P8: 7 | S8: 7 | V8: 7 | Y8: 7 | AB8: 7 | AE8: 7 | AH8: 7
A9: 8 | B9: -335 | D9: 8 | G9: 8 | J9: 8 | M9: 8 | P9: 8 | S9: 8 | V9: 8 | Y9: 8 | AB9: 8 | AE9: 8 | AH9: 8
A10: 9 | B10: -350 | D10: 9 | E10: 2325 | G10: 9 | H10: 1190 | J10: 9 | M10: 9 | P10: 9 | S10: 9 | V10: 9 | Y10: 9 | AB10: 9 | AE10: 9 | AH10: 9
A11: 10 | D11: 10 | E11: 50 | G11: 10 | H11: =1955-915 | J11: 10 | M11: 10 | P11: 10 | S11: 10 | V11: 10 | Y11: 10 | AB11: 10 | AE11: 10 | AH11: 10
A12: 11 | D12: 11 | E12: 890 | G12: 11 | H12: -2305 | J12: 11 | M12: 11 | P12: 11 | S12: 11 | V12: 11 | Y12: 11 | AB12: 11 | AE12: 11 | AH12: 11
A13: 12 | B13: 10 | D13: 12 | E13: =-2155+2245 | G13: 12 | J13: 12 | M13: 12 | P13: 12 | S13: 12 | V13: 12 | Y13: 12 | AB13: 12 | AE13: 12 | AH13: 12
A14: 13 | B14: -2060 | D14: 13 | G14: 13 | H14: 60 | J14: 13 | M14: 13 | P14: 13 | S14: 13 | V14: 13 | Y14: 13 | AB14: 13 | AE14: 13 | AH14: 13
A15: 14 | B15: 1695 | D15: 14 | G15: 14 | J15: 14 | M15: 14 | P15: 14 | S15: 14 | V15: 14 | Y15: 14 | AB15: 14 | AE15: 14 | AH15: 14
A16: 15 | D16: 15 | G16: 15 | J16: 15 | M16: 15 | P16: 15 | S16: 15 | V16: 15 | Y16: 15 | AB16: 15 | AE16: 15 | AH16: 15
A17: 16 | B17: 285 | D17: 16 | G17: 16 | J17: 16 | M17: 16 | P17: 16 | S17: 16 | V17: 16 | Y17: 16 | AB17: 16 | AE17: 16 | AH17: 16
A18: 17 | D18: 17 | G18: 17 | H18: =-418-605 | J18: 17 | M18: 17 | P18: 17 | S18: 17 | V18: 17 | Y18: 17 | AB18: 17 | AE18: 17 | AH18: 17
A19: 18 | D19: 18 | G19: 18 | J19: 18 | M19: 18 | P19: 18 | S19: 18 | V19: 18 | Y19: 18 | AB19: 18 | AE19: 18 | AH19: 18
A20: 19 | D20: 19 | E20: =-580+35 | G20: 19 | H20: 1100 | J20: 19 | M20: 19 | P20: 19 | S20: 19 | V20: 19 | Y20: 19 | AB20: 19 | AE20: 19 | AH20: 19
A21: 20 | B21: =-645+5660 | D21: 20 | E21: =325-4580 | G21: 20 | H21: -3440 | J21: 20 | M21: 20 | P21: 20 | S21: 20 | V21: 20 | Y21: 20 | AB21: 20 | AE21: 20 | AH21: 20
A22: 21 | B22: 2495 | D22: 21 | G22: 21 | J22: 21 | M22: 21 | P22: 21 | S22: 21 | V22: 21 | Y22: 21 | AB22: 21 | AE22: 21 | AH22: 21
A23: 22 | D23: 22 | G23: 22 | J23: 22 | M23: 22 | P23: 22 | S23: 22 | V23: 22 | Y23: 22 | AB23: 22 | AE23: 22 | AH23: 22
A24: 23 | B24: 335 | D24: 23 | E24: =-910+3775 | G24: 23 | H24: 1845 | J24: 23 | M24: 23 | P24: 23 | S24: 23 | V24: 23 | Y24: 23 | AB24: 23 | AE24: 23 | AH24: 23
A25: 24 | D25: 24 | E25: 2520 | G25: 24 | H25: =-2420+220 | J25: 24 | M25: 24 | P25: 24 | S25: 24 | V25: 24 | Y25: 24 | AB25: 24 | AE25: 24 | AH25: 24
A26: 25 | D26: 25 | E26: 1880 | G26: 25 | H26: =430+1004 | J26: 25 | M26: 25 | P26: 25 | S26: 25 | V26: 25 | Y26: 25 | AB26: 25 | AE26: 25 | AH26: 25
A27: 26 | B27: 135 | D27: 26 | G27: 26 | H27: =3340+527 | J27: 26 | M27: 26 | P27: 26 | S27: 26 | V27: 26 | Y27: 26 | AB27: 26 | AE27: 26 | AH27: 26
A28: 27 | B28: 1616 | D28: 27 | E28: =-1060-414 | G28: 27 | H28: 1126 | J28: 27 | M28: 27 | P28: 27 | S28: 27 | V28: 27 | Y28: 27 | AB28: 27 | AE28: 27 | AH28: 27
A29: 28 | B29: -460 | D29: 28 | G29: 28 | J29: 28 | M29: 28 | P29: 28 | S29: 28 | V29: 28 | Y29: 28 | AB29: 28 | AE29: 28 | AH29: 28
A30: 29 | B30: =2810+720-1095 | D30: 29 | G30: 29 | J30: 29 | M30: 29 | P30: 29 | S30: 29 | V30: 29 | Y30: 29 | AB30: 29 | AE30: 29 | AH30: 29
A31: 30 | B31: =-1270-2210 | D31: 30 | G31: 30 | H31: 1783 | J31: 30 | M31: 30 | P31: 30 | S31: 30 | V31: 30 | Y31: 30 | AB31: 30 | AE31: 30 | AH31: 30
A32: 31 | D32: 31 | G32: 31 | H32: =1390+2345 | J32: 31 | M32: 31 | P32: 31 | S32: 31 | V32: 31 | Y32: 31 | AB32: 31 | AE32: 31 | AH32: 31
A35: Total | B35: =SUM(B2:B34) | E35: =SUM(E2:E27) | H35: =SUM(H2:H34) | K35: =SUM(K2:K34) | N35: =SUM(N2:N34) | Q35: =SUM(Q2:Q34) | T35: =SUM(T2:T34) | W35: =SUM(W2:W34) | Z35: =SUM(Z2:Z34) | AC35: =SUM(AC2:AC34) | AF35: =SUM(AF2:AF34) | AI35: =SUM(AI2:AI34)

Sheet Auto JSP
A1: January | D1: February | G1: March | J1: April | M1: May | P1: Jun | S1: Jul | V1: Aug | Y1: Sep | AB1: Oct | AE1: Nov | AH1: Dec
A2: 1 | D2: 1 | G2: 1 | J2: 1 | M2: 1 | P2: 1 | S2: 1 | V2: 1 | Y2: 1 | AB2: 1 | AE2: 1 | AH2: 1
A3: 2 | D3: 2 | E3: -730 | G3: 2 | J3: 2 | M3: 2 | P3: 2 | S3: 2 | V3: 2 | Y3: 2 | AB3: 2 | AE3: 2 | AH3: 2
A4: 3 | D4: 3 | G4: 3 | J4: 3 | M4: 3 | P4: 3 | S4: 3 | V4: 3 | Y4: 3 | AB4: 3 | AE4: 3 | AH4: 3
A5: 4 | D5: 4 | G5: 4 | H5: -740 | J5: 4 | M5: 4 | P5: 4 | S5: 4 | V5: 4 | Y5: 4 | AB5: 4 | AE5: 4 | AH5: 4
A6: 5 | D6: 5 | G6: 5 | J6: 5 | M6: 5 | P6: 5 | S6: 5 | V6: 5 | Y6: 5 | AB6: 5 | AE6: 5 | AH6: 5
A7: 6 | B7: 510 | D7: 6 | E7: 500 | G7: 6 | J7: 6 | M7: 6 | P7: 6 | S7: 6 | V7: 6 | Y7: 6 | AB7: 6 | AE7: 6 | AH7: 6
A8: 7 | D8: 7 | G8: 7 | J8: 7 | M8: 7 | P8: 7 | S8: 7 | V8: 7 | Y8: 7 | AB8: 7 | AE8: 7 | AH8: 7
A9: 8 | D9: 8 | G9: 8 | J9: 8 | M9: 8 | P9: 8 | S9: 8 | V9: 8 | Y9: 8 | AB9: 8 | AE9: 8 | AH9: 8
A10: 9 | B10: 500 | D10: 9 | E10: -222 | G10: 9 | J10: 9 | M10: 9 | P10: 9 | S10: 9 | V10: 9 | Y10: 9 | AB10: 9 | AE10: 9 | AH10: 9
A11: 10 | D11: 10 | G11: 10 | H11: -280 | J11: 10 | M11: 10 | P11: 10 | S11: 10 | V11: 10 | Y11: 10 | AB11: 10 | AE11: 10 | AH11: 10
A12: 11 | D12: 11 | G12: 11 | J12: 11 | M12: 11 | P12: 11 | S12: 11 | V12: 11 | Y12: 11 | AB12: 11 | AE12: 11 | AH12: 11
A13: 12 | D13: 12 | G13: 12 | J13: 12 | M13: 12 | P13: 12 | S13: 12 | V13: 12 | Y13: 12 | AB13: 12 | AE13: 12 | AH13: 12
A14: 13 | D14: 13 | G14: 13 | J14: 13 | M14: 13 | P14: 13 | S14: 13 | V14: 13 | Y14: 13 | AB14: 13 | AE14: 13 | AH14: 13
A15: 14 | D15: 14 | G15: 14 | J15: 14 | M15: 14 | P15: 14 | S15: 14 | V15: 14 | Y15: 14 | AB15: 14 | AE15: 14 | AH15: 14
A16: 15 | D16: 15 | G16: 15 | J16: 15 | M16: 15 | P16: 15 | S16: 15 | V16: 15 | Y16: 15 | AB16: 15 | AE16: 15 | AH16: 15
A17: 16 | D17: 16 | G17: 16 | J17: 16 | M17: 16 | P17: 16 | S17: 16 | V17: 16 | Y17: 16 | AB17: 16 | AE17: 16 | AH17: 16
A18: 17 | D18: 17 | G18: 17 | J18: 17 | M18: 17 | P18: 17 | S18: 17 | V18: 17 | Y18: 17 | AB18: 17 | AE18: 17 | AH18: 17
A19: 18 | D19: 18 | E19: -1470 | G19: 18 | J19: 18 | M19: 18 | P19: 18 | S19: 18 | V19: 18 | Y19: 18 | AB19: 18 | AE19: 18 | AH19: 18
A20: 19 | D20: 19 | G20: 19 | J20: 19 | M20: 19 | P20: 19 | S20: 19 | V20: 19 | Y20: 19 | AB20: 19 | AE20: 19 | AH20: 19
A21: 20 | D21: 20 | E21: -150 | G21: 20 | J21: 20 | M21: 20 | P21: 20 | S21: 20 | V21: 20 | Y21: 20 | AB21: 20 | AE21: 20 | AH21: 20
A22: 21 | D22: 21 | G22: 21 | J22: 21 | M22: 21 | P22: 21 | S22: 21 | V22: 21 | Y22: 21 | AB22: 21 | AE22: 21 | AH22: 21
A23: 22 | D23: 22 | G23: 22 | J23: 22 | M23: 22 | P23: 22 | S23: 22 | V23: 22 | Y23: 22 | AB23: 22 | AE23: 22 | AH23: 22
A24: 23 | D24: 23 | G24: 23 | J24: 23 | M24: 23 | P24: 23 | S24: 23 | V24: 23 | Y24: 23 | AB24: 23 | AE24: 23 | AH24: 23
A25: 24 | D25: 24 | E25: -650 | G25: 24 | J25: 24 | M25: 24 | P25: 24 | S25: 24 | V25: 24 | Y25: 24 | AB25: 24 | AE25: 24 | AH25: 24
A26: 25 | D26: 25 | E26: 450 | G26: 25 | J26: 25 | M26: 25 | P26: 25 | S26: 25 | V26: 25 | Y26: 25 | AB26: 25 | AE26: 25 | AH26: 25
A27: 26 | B27: -260 | D27: 26 | G27: 26 | J27: 26 | M27: 26 | P27: 26 | S27: 26 | V27: 26 | Y27: 26 | AB27: 26 | AE27: 26 | AH27: 26
A28: 27 | D28: 27 | G28: 27 | J28: 27 | M28: 27 | P28: 27 | S28: 27 | V28: 27 | Y28: 27 | AB28: 27 | AE28: 27 | AH28: 27
A29: 28 | D29: 28 | G29: 28 | J29: 28 | M29: 28 | P29: 28 | S29: 28 | V29: 28 | Y29: 28 | AB29: 28 | AE29: 28 | AH29: 28
A30: 29 | D30: 29 | G30: 29 | J30: 29 | M30: 29 | P30: 29 | S30: 29 | V30: 29 | Y30: 29 | AB30: 29 | AE30: 29 | AH30: 29
A31: 30 | D31: 30 | G31: 30 | J31: 30 | M31: 30 | P31: 30 | S31: 30 | V31: 30 | Y31: 30 | AB31: 30 | AE31: 30 | AH31: 30
A32: 31 | D32: 31 | G32: 31 | J32: 31 | M32: 31 | P32: 31 | S32: 31 | V32: 31 | Y32: 31 | AB32: 31 | AE32: 31 | AH32: 31
A35: Total | B35: =SUM(B2:B34) | E35: =SUM(E2:E27) | H35: =SUM(H2:H34) | K35: =SUM(K2:K34) | N35: =SUM(N2:N34) | Q35: =SUM(Q2:Q34) | T35: =SUM(T2:T34) | W35: =SUM(W2:W34) | Z35: =SUM(Z2:Z34) | AC35: =SUM(AC2:AC34) | AF35: =SUM(AF2:AF34) | AI35: =SUM(AI2:AI34)

Sheet Wed Thu RIC
A1: January | D1: February | G1: March | J1: April | M1: May | P1: Jun | S1: Jul | V1: Aug | Y1: Sep | AB1: Oct | AE1: Nov | AH1: Dec
A2: 1 | D2: 1 | G2: 1 | J2: 1 | M2: 1 | P2: 1 | S2: 1 | V2: 1 | Y2: 1 | AB2: 1 | AE2: 1 | AH2: 1
A3: 2 | D3: 2 | G3: 2 | J3: 2 | M3: 2 | P3: 2 | S3: 2 | V3: 2 | Y3: 2 | AB3: 2 | AE3: 2 | AH3: 2
A4: 3 | D4: 3 | G4: 3 | J4: 3 | M4: 3 | P4: 3 | S4: 3 | V4: 3 | Y4: 3 | AB4: 3 | AE4: 3 | AH4: 3
A5: 4 | D5: 4 | G5: 4 | H5: -3880 | J5: 4 | M5: 4 | P5: 4 | S5: 4 | V5: 4 | Y5: 4 | AB5: 4 | AE5: 4 | AH5: 4
A6: 5 | D6: 5 | G6: 5 | J6: 5 | M6: 5 | P6: 5 | S6: 5 | V6: 5 | Y6: 5 | AB6: 5 | AE6: 5 | AH6: 5
A7: 6 | D7: 6 | G7: 6 | J7: 6 | M7: 6 | P7: 6 | S7: 6 | V7: 6 | Y7: 6 | AB7: 6 | AE7: 6 | AH7: 6
A8: 7 | D8: 7 | G8: 7 | J8: 7 | M8: 7 | P8: 7 | S8: 7 | V8: 7 | Y8: 7 | AB8: 7 | AE8: 7 | AH8: 7
A9: 8 | D9: 8 | G9: 8 | J9: 8 | M9: 8 | P9: 8 | S9: 8 | V9: 8 | Y9: 8 | AB9: 8 | AE9: 8 | AH9: 8
A10: 9 | D10: 9 | G10: 9 | J10: 9 | M10: 9 | P10: 9 | S10: 9 | V10: 9 | Y10: 9 | AB10: 9 | AE10: 9 | AH10: 9
A11: 10 | D11: 10 | G11: 10 | J11: 10 | M11: 10 | P11: 10 | S11: 10 | V11: 10 | Y11: 10 | AB11: 10 | AE11: 10 | AH11: 10
A12: 11 | D12: 11 | G12: 11 | H12: -175 | J12: 11 | M12: 11 | P12: 11 | S12: 11 | V12: 11 | Y12: 11 | AB12: 11 | AE12: 11 | AH12: 11
A13: 12 | D13: 12 | G13: 12 | J13: 12 | M13: 12 | P13: 12 | S13: 12 | V13: 12 | Y13: 12 | AB13: 12 | AE13: 12 | AH13: 12
A14: 13 | D14: 13 | G14: 13 | J14: 13 | M14: 13 | P14: 13 | S14: 13 | V14: 13 | Y14: 13 | AB14: 13 | AE14: 13 | AH14: 13
A15: 14 | D15: 14 | G15: 14 | J15: 14 | M15: 14 | P15: 14 | S15: 14 | V15: 14 | Y15: 14 | AB15: 14 | AE15: 14 | AH15: 14
A16: 15 | D16: 15 | G16: 15 | J16: 15 | M16: 15 | P16: 15 | S16: 15 | V16: 15 | Y16: 15 | AB16: 15 | AE16: 15 | AH16: 15
A17: 16 | D17: 16 | G17: 16 | J17: 16 | M17: 16 | P17: 16 | S17: 16 | V17: 16 | Y17: 16 | AB17: 16 | AE17: 16 | AH17: 16
A18: 17 | D18: 17 | G18: 17 | J18: 17 | M18: 17 | P18: 17 | S18: 17 | V18: 17 | Y18: 17 | AB18: 17 | AE18: 17 | AH18: 17
A19: 18 | D19: 18 | E19: 220 | G19: 18 | J19: 18 | M19: 18 | P19: 18 | S19: 18 | V19: 18 | Y19: 18 | AB19: 18 | AE19: 18 | AH19: 18
A20: 19 | D20: 19 | G20: 19 | J20: 19 | M20: 19 | P20: 19 | S20: 19 | V20: 19 | Y20: 19 | AB20: 19 | AE20: 19 | AH20: 19
A21: 20 | D21: 20 | G21: 20 | J21: 20 | M21: 20 | P21: 20 | S21: 20 | V21: 20 | Y21: 20 | AB21: 20 | AE21: 20 | AH21: 20
A22: 21 | B22: 1665 | D22: 21 | G22: 21 | J22: 21 | M22: 21 | P22: 21 | S22: 21 | V22: 21 | Y22: 21 | AB22: 21 | AE22: 21 | AH22: 21
A23: 22 | B23: -2130 | D23: 22 | G23: 22 | J23: 22 | M23: 22 | P23: 22 | S23: 22 | V23: 22 | Y23: 22 | AB23: 22 | AE23: 22 | AH23: 22
A24: 23 | D24: 23 | G24: 23 | J24: 23 | M24: 23 | P24: 23 | S24: 23 | V24: 23 | Y24: 23 | AB24: 23 | AE24: 23 | AH24: 23
A25: 24 | D25: 24 | G25: 24 | J25: 24 | M25: 24 | P25: 24 | S25: 24 | V25: 24 | Y25: 24 | AB25: 24 | AE25: 24 | AH25: 24
A26: 25 | D26: 25 | G26: 25 | J26: 25 | M26: 25 | P26: 25 | S26: 25 | V26: 25 | Y26: 25 | AB26: 25 | AE26: 25 | AH26: 25
A27: 26 | D27: 26 | G27: 26 | J27: 26 | M27: 26 | P27: 26 | S27: 26 | V27: 26 | Y27: 26 | AB27: 26 | AE27: 26 | AH27: 26
A28: 27 | D28: 27 | G28: 27 | J28: 27 | M28: 27 | P28: 27 | S28: 27 | V28: 27 | Y28: 27 | AB28: 27 | AE28: 27 | AH28: 27
A29: 28 | D29: 28 | G29: 28 | J29: 28 | M29: 28 | P29: 28 | S29: 28 | V29: 28 | Y29: 28 | AB29: 28 | AE29: 28 | AH29: 28
A30: 29 | D30: 29 | G30: 29 | J30: 29 | M30: 29 | P30: 29 | S30: 29 | V30: 29 | Y30: 29 | AB30: 29 | AE30: 29 | AH30: 29
A31: 30 | D31: 30 | G31: 30 | J31: 30 | M31: 30 | P31: 30 | S31: 30 | V31: 30 | Y31: 30 | AB31: 30 | AE31: 30 | AH31: 30
A32: 31 | D32: 31 | G32: 31 | J32: 31 | M32: 31 | P32: 31 | S32: 31 | V32: 31 | Y32: 31 | AB32: 31 | AE32: 31 | AH32: 31
A35: Total | B35: =SUM(B2:B34) | E35: =SUM(E2:E27) | H35: =SUM(H2:H34) | K35: =SUM(K2:K34) | N35: =SUM(N2:N34) | Q35: =SUM(Q2:Q34) | T35: =SUM(T2:T34) | W35: =SUM(W2:W34) | Z35: =SUM(Z2:Z34) | AC35: =SUM(AC2:AC34) | AF35: =SUM(AF2:AF34) | AI35: =SUM(AI2:AI34)

Sheet Lottery
A1: January | D1: February | G1: March | J1: April | M1: May | P1: Jun | S1: Jul | V1: Aug | Y1: Sep | AB1: Oct | AE1: Nov | AH1: Dec
A2: 1 | D2: 1 | G2: 1 | J2: 1 | M2: 1 | P2: 1 | S2: 1 | V2: 1 | Y2: 1 | AB2: 1 | AE2: 1 | AH2: 1
A3: 2 | D3: 2 | G3: 2 | J3: 2 | M3: 2 | P3: 2 | S3: 2 | V3: 2 | Y3: 2 | AB3: 2 | AE3: 2 | AH3: 2
A4: 3 | D4: 3 | G4: 3 | J4: 3 | M4: 3 | P4: 3 | S4: 3 | V4: 3 | Y4: 3 | AB4: 3 | AE4: 3 | AH4: 3
A5: 4 | D5: 4 | G5: 4 | J5: 4 | M5: 4 | P5: 4 | S5: 4 | V5: 4 | Y5: 4 | AB5: 4 | AE5: 4 | AH5: 4
A6: 5 | D6: 5 | G6: 5 | J6: 5 | M6: 5 | P6: 5 | S6: 5 | V6: 5 | Y6: 5 | AB6: 5 | AE6: 5 | AH6: 5
A7: 6 | D7: 6 | G7: 6 | J7: 6 | M7: 6 | P7: 6 | S7: 6 | V7: 6 | Y7: 6 | AB7: 6 | AE7: 6 | AH7: 6
A8: 7 | D8: 7 | G8: 7 | J8: 7 | M8: 7 | P8: 7 | S8: 7 | V8: 7 | Y8: 7 | AB8: 7 | AE8: 7 | AH8: 7
A9: 8 | D9: 8 | G9: 8 | J9: 8 | M9: 8 | P9: 8 | S9: 8 | V9: 8 | Y9: 8 | AB9: 8 | AE9: 8 | AH9: 8
A10: 9 | D10: 9 | G10: 9 | J10: 9 | M10: 9 | P10: 9 | S10: 9 | V10: 9 | Y10: 9 | AB10: 9 | AE10: 9 | AH10: 9
A11: 10 | D11: 10 | G11: 10 | J11: 10 | M11: 10 | P11: 10 | S11: 10 | V11: 10 | Y11: 10 | AB11: 10 | AE11: 10 | AH11: 10
A12: 11 | D12: 11 | G12: 11 | J12: 11 | M12: 11 | P12: 11 | S12: 11 | V12: 11 | Y12: 11 | AB12: 11 | AE12: 11 | AH12: 11
A13: 12 | D13: 12 | E13: -385 | G13: 12 | J13: 12 | M13: 12 | P13: 12 | S13: 12 | V13: 12 | Y13: 12 | AB13: 12 | AE13: 12 | AH13: 12
